Attaching to dev_ella_1
[36mella_1        |[0m 2020-09-17 05:47:41,713 INFO RPC interface 'supervisor' initialized
[36mella_1        |[0m 2020-09-17 05:47:41,713 INFO RPC interface 'supervisor' initialized
[36mella_1        |[0m 2020-09-17 05:47:41,714 CRIT Server 'unix_http_server' running without any HTTP authentication checking
[36mella_1        |[0m 2020-09-17 05:47:41,714 CRIT Server 'unix_http_server' running without any HTTP authentication checking
[36mella_1        |[0m 2020-09-17 05:47:41,714 INFO supervisord started with pid 1
[36mella_1        |[0m 2020-09-17 05:47:41,714 INFO supervisord started with pid 1
[36mella_1        |[0m 2020-09-17 05:47:42,722 INFO spawned: 'docs' with pid 10
[36mella_1        |[0m 2020-09-17 05:47:42,722 INFO spawned: 'docs' with pid 10
[36mella_1        |[0m 2020-09-17 05:47:42,730 INFO spawned: 'polling' with pid 11
[36mella_1        |[0m 2020-09-17 05:47:42,730 INFO spawned: 'polling' with pid 11
[36mella_1        |[0m 2020-09-17 05:47:42,734 INFO spawned: 'postgres' with pid 13
[36mella_1        |[0m 2020-09-17 05:47:42,734 INFO spawned: 'postgres' with pid 13
[36mella_1        |[0m 2020-09-17 05:47:42,739 INFO spawned: 'web' with pid 14
[36mella_1        |[0m 2020-09-17 05:47:42,739 INFO spawned: 'web' with pid 14
[36mella_1        |[0m 2020-09-17 05:47:42,745 INFO spawned: 'webpack' with pid 17
[36mella_1        |[0m 2020-09-17 05:47:42,745 INFO spawned: 'webpack' with pid 17
[36mella_1        |[0m Init of Postgres cluster in /pg-data
[36mella_1        |[0m Creating database cluster in /pg-data
[36mella_1        |[0m The files belonging to this database system will be owned by user "ella-user".
[36mella_1        |[0m This user must also own the server process.
[36mella_1        |[0m 
[36mella_1        |[0m The database cluster will be initialized with locale "C.UTF-8".
[36mella_1        |[0m The default database encoding has accordingly been set to "UTF8".
[36mella_1        |[0m The default text search configuration will be set to "english".
[36mella_1        |[0m 
[36mella_1        |[0m Data page checksums are disabled.
[36mella_1        |[0m 
[36mella_1        |[0m fixing permissions on existing directory /pg-data ... ok
[36mella_1        |[0m creating subdirectories ... ok
[36mella_1        |[0m selecting default max_connections ... 100
[36mella_1        |[0m selecting default shared_buffers ... 128MB
[36mella_1        |[0m selecting default timezone ... Etc/UTC
[36mella_1        |[0m selecting dynamic shared memory implementation ... posix
[36mella_1        |[0m creating configuration files ... ok
[36mella_1        |[0m running bootstrap script ... yarn run v1.22.5
[36mella_1        |[0m ok
[36mella_1        |[0m performing post-bootstrap initialization ... 2020-09-17 05:47:43,802 INFO success: docs entered RUNNING state, process has stayed up for > than 1 seconds (startsecs)
[36mella_1        |[0m 2020-09-17 05:47:43,802 INFO success: docs entered RUNNING state, process has stayed up for > than 1 seconds (startsecs)
[36mella_1        |[0m 2020-09-17 05:47:43,802 INFO success: polling entered RUNNING state, process has stayed up for > than 1 seconds (startsecs)
[36mella_1        |[0m 2020-09-17 05:47:43,802 INFO success: polling entered RUNNING state, process has stayed up for > than 1 seconds (startsecs)
[36mella_1        |[0m 2020-09-17 05:47:43,802 INFO success: postgres entered RUNNING state, process has stayed up for > than 1 seconds (startsecs)
[36mella_1        |[0m 2020-09-17 05:47:43,802 INFO success: postgres entered RUNNING state, process has stayed up for > than 1 seconds (startsecs)
[36mella_1        |[0m 2020-09-17 05:47:43,802 INFO success: web entered RUNNING state, process has stayed up for > than 1 seconds (startsecs)
[36mella_1        |[0m 2020-09-17 05:47:43,802 INFO success: web entered RUNNING state, process has stayed up for > than 1 seconds (startsecs)
[36mella_1        |[0m 2020-09-17 05:47:43,803 INFO success: webpack entered RUNNING state, process has stayed up for > than 1 seconds (startsecs)
[36mella_1        |[0m 2020-09-17 05:47:43,803 INFO success: webpack entered RUNNING state, process has stayed up for > than 1 seconds (startsecs)
[36mella_1        |[0m $ webpack --mode development --watch --hide-modules
[36mella_1        |[0m /dist/ella-python/lib/python3.7/site-packages/apispec/ext/marshmallow/openapi.py:612: UserWarning: Only explicitly-declared fields will be included in the Schema Object. Fields defined in Meta.fields or Meta.additional are ignored.
[36mella_1        |[0m   'Only explicitly-declared fields will be included in the Schema Object. '
[36mella_1        |[0m /ella/src/api/v1/apispec_restful.py:69: YAMLLoadWarning: calling yaml.load() without Loader=... is deprecated, as the default Loader is unsafe. Please read https://msg.pyyaml.org/load for full details.
[36mella_1        |[0m   operations[method].update(yaml.load(doc))
[36mella_1        |[0m 2020-09-17 05:47:45,482 INFO exited: polling (exit status 1; not expected)
[36mella_1        |[0m 2020-09-17 05:47:45,482 INFO exited: polling (exit status 1; not expected)
[36mella_1        |[0m ok
[36mella_1        |[0m syncing data to disk ... 2020-09-17 05:47:45,628 INFO spawned: 'polling' with pid 89
[36mella_1        |[0m 2020-09-17 05:47:45,628 INFO spawned: 'polling' with pid 89
[36mella_1        |[0m !!!!!DEVELOPMENT MODE!!!!!
[36mella_1        |[0m  * Serving Flask app "api" (lazy loading)
[36mella_1        |[0m  * Environment: production
[36mella_1        |[0m    WARNING: Do not use the development server in a production environment.
[36mella_1        |[0m    Use a production WSGI server instead.
[36mella_1        |[0m  * Debug mode: off
[36mella_1        |[0m 2020-09-17 05:47:46,432 [INFO] werkzeug:  * Running on http://0.0.0.0:5000/ (Press CTRL+C to quit)
[36mella_1        |[0m 2020-09-17 05:47:46,433 [INFO] werkzeug:  * Restarting with stat
[36mella_1        |[0m 2020-09-17 05:47:47,181 INFO success: polling entered RUNNING state, process has stayed up for > than 1 seconds (startsecs)
[36mella_1        |[0m 2020-09-17 05:47:47,181 INFO success: polling entered RUNNING state, process has stayed up for > than 1 seconds (startsecs)
[36mella_1        |[0m clean-webpack-plugin: /ella/src/webui/build/* has been removed.
[36mella_1        |[0m 
[36mella_1        |[0m webpack is watching the filesâ€¦
[36mella_1        |[0m 
[36mella_1        |[0m Live Reload listening on port 35729
[36mella_1        |[0m 
[36mella_1        |[0m ok
[36mella_1        |[0m 
[36mella_1        |[0m Success. You can now start the database server using:
[36mella_1        |[0m 
[36mella_1        |[0m     /usr/lib/postgresql/10/bin/pg_ctl -D /pg-data -l logfile start
[36mella_1        |[0m 
[36mella_1        |[0m Starting PostgreSQL
[36mella_1        |[0m 2020-09-17 05:47:47.876 UTC [13] LOG:  listening on IPv4 address "127.0.0.1", port 5432
[36mella_1        |[0m 2020-09-17 05:47:47.882 UTC [13] LOG:  listening on Unix socket "/socket/.s.PGSQL.5432"
[36mella_1        |[0m 2020-09-17 05:47:47.908 UTC [146] LOG:  database system was shut down at 2020-09-17 05:47:45 UTC
[36mella_1        |[0m 2020-09-17 05:47:47.918 UTC [13] LOG:  database system is ready to accept connections
[36mella_1        |[0m /dist/ella-python/lib/python3.7/site-packages/apispec/ext/marshmallow/openapi.py:612: UserWarning: Only explicitly-declared fields will be included in the Schema Object. Fields defined in Meta.fields or Meta.additional are ignored.
[36mella_1        |[0m   'Only explicitly-declared fields will be included in the Schema Object. '
[36mella_1        |[0m /ella/src/api/v1/apispec_restful.py:69: YAMLLoadWarning: calling yaml.load() without Loader=... is deprecated, as the default Loader is unsafe. Please read https://msg.pyyaml.org/load for full details.
[36mella_1        |[0m   operations[method].update(yaml.load(doc))
[36mella_1        |[0m Enabled python remote debugging at port 5678
[36mella_1        |[0m !!!!!DEVELOPMENT MODE!!!!!
[36mella_1        |[0m 
[36mella_1        |[0m --------------------- Unused Files ---------------------
[36mella_1        |[0m 
[36mella_1        |[0m /ella/src/webui/src/js/store/fixtures/testData.js
[36mella_1        |[0m 
[36mella_1        |[0m /ella/src/webui/src/js/store/modules/views/workflows/alleleSidebar/computed/getNotRelevantById.js
[36mella_1        |[0m 
[36mella_1        |[0m /ella/src/webui/src/js/store/modules/views/workflows/alleleSidebar/computed/hasReferencesById.js
[36mella_1        |[0m 
[36mella_1        |[0m /ella/src/webui/src/js/store/modules/views/workflows/alleleSidebar/computed/isHomozygousById.js
[36mella_1        |[0m 
[36mella_1        |[0m /ella/src/webui/src/js/store/modules/views/workflows/alleleSidebar/computed/isLowQualById.js
[36mella_1        |[0m 
[36mella_1        |[0m /ella/src/webui/src/js/store/modules/views/workflows/alleleSidebar/computed/isSelected.js
[36mella_1        |[0m 
[36mella_1        |[0m There are 6 unused files (Â¬Âº-Â°)Â¬. 
[36mella_1        |[0m 
[36mella_1        |[0m Please be careful if you want to remove them.
[36mella_1        |[0m 
[36mella_1        |[0m 
[36mella_1        |[0m --------------------- Unused Exports ---------------------
[36mella_1        |[0m 
[36mella_1        |[0m Perfect, there is nothing to do Ù©(â—•â€¿â—•ï½¡)Û¶.
[36mella_1        |[0m Live Reload: Reloading fonts/SourceCodePro-Regular.otf.woff2, fonts/SourceSansPro-Bold.otf.woff2, fonts/SourceSansPro-Light.otf.woff2, fonts/SourceSansPro-Regular.otf.woff2, fonts/SourceSansPro-Semibold.otf.woff2, fonts/WorkSans-Bold.woff2, fonts/WorkSans-ExtraLight.woff2, fonts/WorkSans-Light.woff2, fonts/WorkSans-Medium.woff2, fonts/WorkSans-Regular.woff2, fonts/WorkSans-SemiBold.woff2, fonts/WorkSans-Thin.woff2, app.css, app.js, index.html
[36mella_1        |[0m Hash: c411992386af58641347
[36mella_1        |[0m Version: webpack 4.16.3
[36mella_1        |[0m Time: 33667ms
[36mella_1        |[0m Built at: 09/17/2020 5:48:20 AM
[36mella_1        |[0m                                  Asset       Size  Chunks                    Chunk Names
[36mella_1        |[0m             fonts/WorkSans-Light.woff2   48.3 KiB          [emitted]         
[36mella_1        |[0m  fonts/SourceCodePro-Regular.otf.woff2   74.5 KiB          [emitted]         
[36mella_1        |[0m    fonts/SourceSansPro-Light.otf.woff2   97.2 KiB          [emitted]         
[36mella_1        |[0m  fonts/SourceSansPro-Regular.otf.woff2    100 KiB          [emitted]         
[36mella_1        |[0m fonts/SourceSansPro-Semibold.otf.woff2    101 KiB          [emitted]         
[36mella_1        |[0m              fonts/WorkSans-Bold.woff2     51 KiB          [emitted]         
[36mella_1        |[0m        fonts/WorkSans-ExtraLight.woff2   47.6 KiB          [emitted]         
[36mella_1        |[0m     fonts/SourceSansPro-Bold.otf.woff2    101 KiB          [emitted]         
[36mella_1        |[0m            fonts/WorkSans-Medium.woff2   50.2 KiB          [emitted]         
[36mella_1        |[0m           fonts/WorkSans-Regular.woff2   46.9 KiB          [emitted]         
[36mella_1        |[0m          fonts/WorkSans-SemiBold.woff2   50.5 KiB          [emitted]         
[36mella_1        |[0m              fonts/WorkSans-Thin.woff2   46.1 KiB          [emitted]         
[36mella_1        |[0m                                app.css    371 KiB     app  [emitted]  [big]  app
[36mella_1        |[0m                                 app.js     18 MiB     app  [emitted]  [big]  app
[36mella_1        |[0m                             index.html  578 bytes          [emitted]         
[36mella_1        |[0m Entrypoint app [big] = app.css app.js
[36mella_1        |[0m Child html-webpack-plugin for "index.html":
[36mella_1        |[0m      1 asset
[36mella_1        |[0m     Entrypoint undefined = index.html
[36mella_1        |[0m Child mini-css-extract-plugin ../dist/node_modules/css-loader/index.js!../dist/node_modules/sass-loader/lib/loader.js!../dist/node_modules/tippy.js/dist/tippy.css:
[36mella_1        |[0m     Entrypoint mini-css-extract-plugin = *
[36mella_1        |[0m Child mini-css-extract-plugin ../dist/node_modules/css-loader/index.js!../dist/node_modules/sass-loader/lib/loader.js!src/webui/src/css/base.css:
[36mella_1        |[0m     Entrypoint mini-css-extract-plugin = *
[36mella_1        |[0m Child mini-css-extract-plugin ../dist/node_modules/css-loader/index.js!../dist/node_modules/sass-loader/lib/loader.js!src/webui/src/sass/main.scss:
[36mella_1        |[0m                                      Asset      Size  Chunks             Chunk Names
[36mella_1        |[0m            fonts/WorkSans-ExtraLight.woff2  47.6 KiB          [emitted]  
[36mella_1        |[0m      fonts/SourceCodePro-Regular.otf.woff2  74.5 KiB          [emitted]  
[36mella_1        |[0m        fonts/SourceSansPro-Light.otf.woff2  97.2 KiB          [emitted]  
[36mella_1        |[0m      fonts/SourceSansPro-Regular.otf.woff2   100 KiB          [emitted]  
[36mella_1        |[0m     fonts/SourceSansPro-Semibold.otf.woff2   101 KiB          [emitted]  
[36mella_1        |[0m                  fonts/WorkSans-Bold.woff2    51 KiB          [emitted]  
[36mella_1        |[0m         fonts/SourceSansPro-Bold.otf.woff2   101 KiB          [emitted]  
[36mella_1        |[0m                 fonts/WorkSans-Light.woff2  48.3 KiB          [emitted]  
[36mella_1        |[0m                fonts/WorkSans-Medium.woff2  50.2 KiB          [emitted]  
[36mella_1        |[0m               fonts/WorkSans-Regular.woff2  46.9 KiB          [emitted]  
[36mella_1        |[0m              fonts/WorkSans-SemiBold.woff2  50.5 KiB          [emitted]  
[36mella_1        |[0m                  fonts/WorkSans-Thin.woff2  46.1 KiB          [emitted]  
[36mella_1        |[0m     Entrypoint mini-css-extract-plugin = *
[36mella_1        |[0m 2020-09-17 05:48:27,005 INFO exited: docs (exit status 0; expected)
[36mella_1        |[0m 2020-09-17 05:48:27,005 INFO exited: docs (exit status 0; expected)
[36mella_1        |[0m 2020-09-17 05:52:34.165 UTC [233] ERROR:  relation "broadcast" does not exist at character 171
[36mella_1        |[0m 2020-09-17 05:52:34.165 UTC [233] STATEMENT:  SELECT broadcast.id AS broadcast_id, broadcast.date_created AS broadcast_date_created, broadcast.message AS broadcast_message, broadcast.active AS broadcast_active 
[36mella_1        |[0m 	FROM broadcast 
[36mella_1        |[0m 	WHERE broadcast.active IS true ORDER BY broadcast.date_created
[36mella_1        |[0m 2020-09-17 05:52:34,169 [ERROR] flask.app: Exception on /api/v1/broadcasts/ [GET]
[36mella_1        |[0m Traceback (most recent call last):
[36mella_1        |[0m   File "/dist/ella-python/lib/python3.7/site-packages/flask/app.py", line 1813, in full_dispatch_request
[36mella_1        |[0m     rv = self.dispatch_request()
[36mella_1        |[0m   File "/dist/ella-python/lib/python3.7/site-packages/flask/app.py", line 1799, in dispatch_request
[36mella_1        |[0m     return self.view_functions[rule.endpoint](**req.view_args)
[36mella_1        |[0m   File "/dist/ella-python/lib/python3.7/site-packages/flask_restful/__init__.py", line 458, in wrapper
[36mella_1        |[0m     resp = resource(*args, **kwargs)
[36mella_1        |[0m   File "/dist/ella-python/lib/python3.7/site-packages/flask/views.py", line 88, in view
[36mella_1        |[0m     return self.dispatch_request(*args, **kwargs)
[36mella_1        |[0m   File "/dist/ella-python/lib/python3.7/site-packages/flask_restful/__init__.py", line 573, in dispatch_request
[36mella_1        |[0m     resp = meth(*args, **kwargs)
[36mella_1        |[0m   File "/ella/src/api/util/util.py", line 229, in inner
[36mella_1        |[0m     return func(db.session, *args, **kwargs)
[36mella_1        |[0m   File "/ella/src/api/util/util.py", line 218, in inner
[36mella_1        |[0m     return func(*args, **kwargs)
[36mella_1        |[0m   File "/ella/src/api/util/util.py", line 435, in inner
[36mella_1        |[0m     return func(*args, **kwargs)
[36mella_1        |[0m   File "/ella/src/api/v1/resources/broadcast.py", line 56, in get
[36mella_1        |[0m     .order_by(broadcast.Broadcast.date_created)
[36mella_1        |[0m   File "/dist/ella-python/lib/python3.7/site-packages/sqlalchemy/orm/query.py", line 2843, in all
[36mella_1        |[0m     return list(self)
[36mella_1        |[0m   File "/dist/ella-python/lib/python3.7/site-packages/sqlalchemy/orm/query.py", line 2995, in __iter__
[36mella_1        |[0m     return self._execute_and_instances(context)
[36mella_1        |[0m   File "/dist/ella-python/lib/python3.7/site-packages/sqlalchemy/orm/query.py", line 3018, in _execute_and_instances
[36mella_1        |[0m     result = conn.execute(querycontext.statement, self._params)
[36mella_1        |[0m   File "/dist/ella-python/lib/python3.7/site-packages/sqlalchemy/engine/base.py", line 948, in execute
[36mella_1        |[0m     return meth(self, multiparams, params)
[36mella_1        |[0m   File "/dist/ella-python/lib/python3.7/site-packages/sqlalchemy/sql/elements.py", line 269, in _execute_on_connection
[36mella_1        |[0m     return connection._execute_clauseelement(self, multiparams, params)
[36mella_1        |[0m   File "/dist/ella-python/lib/python3.7/site-packages/sqlalchemy/engine/base.py", line 1060, in _execute_clauseelement
[36mella_1        |[0m     compiled_sql, distilled_params
[36mella_1        |[0m   File "/dist/ella-python/lib/python3.7/site-packages/sqlalchemy/engine/base.py", line 1200, in _execute_context
[36mella_1        |[0m     context)
[36mella_1        |[0m   File "/dist/ella-python/lib/python3.7/site-packages/sqlalchemy/engine/base.py", line 1409, in _handle_dbapi_exception
[36mella_1        |[0m     util.raise_from_cause(newraise, exc_info)
[36mella_1        |[0m   File "/dist/ella-python/lib/python3.7/site-packages/sqlalchemy/util/compat.py", line 265, in raise_from_cause
[36mella_1        |[0m     reraise(type(exception), exception, tb=exc_tb, cause=cause)
[36mella_1        |[0m   File "/dist/ella-python/lib/python3.7/site-packages/sqlalchemy/util/compat.py", line 248, in reraise
[36mella_1        |[0m     raise value.with_traceback(tb)
[36mella_1        |[0m   File "/dist/ella-python/lib/python3.7/site-packages/sqlalchemy/engine/base.py", line 1193, in _execute_context
[36mella_1        |[0m     context)
[36mella_1        |[0m   File "/dist/ella-python/lib/python3.7/site-packages/sqlalchemy/engine/default.py", line 509, in do_execute
[36mella_1        |[0m     cursor.execute(statement, parameters)
[36mella_1        |[0m psycopg2.ProgrammingError: relation "broadcast" does not exist
[36mella_1        |[0m LINE 2: FROM broadcast 
[36mella_1        |[0m              ^
[36mella_1        |[0m 
[36mella_1        |[0m 2020-09-17 05:52:34.188 UTC [233] ERROR:  relation "resourcelog" does not exist at character 13
[36mella_1        |[0m 2020-09-17 05:52:34.188 UTC [233] STATEMENT:  INSERT INTO resourcelog (remote_addr, time, duration, usersession_id, method, resource, query, response, response_size, payload, payload_size, statuscode) VALUES ('172.20.0.1', '2020-09-17T05:52:34.186643+00:00'::timestamptz, 627, NULL, 'GET', '/api/v1/broadcasts/', '', NULL, 36, NULL, 0, 500) RETURNING resourcelog.id
[36mella_1        |[0m 2020-09-17 05:52:34,189 [ERROR] flask.app: Something went wrong when commiting resourcelog entry
[36mella_1        |[0m Traceback (most recent call last):
[36mella_1        |[0m   File "/ella/src/api/main.py", line 47, in after_request
[36mella_1        |[0m     db.session.commit()
[36mella_1        |[0m   File "/dist/ella-python/lib/python3.7/site-packages/sqlalchemy/orm/scoping.py", line 153, in do
[36mella_1        |[0m     return getattr(self.registry(), name)(*args, **kwargs)
[36mella_1        |[0m   File "/dist/ella-python/lib/python3.7/site-packages/sqlalchemy/orm/session.py", line 954, in commit
[36mella_1        |[0m     self.transaction.commit()
[36mella_1        |[0m   File "/dist/ella-python/lib/python3.7/site-packages/sqlalchemy/orm/session.py", line 467, in commit
[36mella_1        |[0m     self._prepare_impl()
[36mella_1        |[0m   File "/dist/ella-python/lib/python3.7/site-packages/sqlalchemy/orm/session.py", line 447, in _prepare_impl
[36mella_1        |[0m     self.session.flush()
[36mella_1        |[0m   File "/dist/ella-python/lib/python3.7/site-packages/sqlalchemy/orm/session.py", line 2313, in flush
[36mella_1        |[0m     self._flush(objects)
[36mella_1        |[0m   File "/dist/ella-python/lib/python3.7/site-packages/sqlalchemy/orm/session.py", line 2440, in _flush
[36mella_1        |[0m     transaction.rollback(_capture_exception=True)
[36mella_1        |[0m   File "/dist/ella-python/lib/python3.7/site-packages/sqlalchemy/util/langhelpers.py", line 66, in __exit__
[36mella_1        |[0m     compat.reraise(exc_type, exc_value, exc_tb)
[36mella_1        |[0m   File "/dist/ella-python/lib/python3.7/site-packages/sqlalchemy/util/compat.py", line 249, in reraise
[36mella_1        |[0m     raise value
[36mella_1        |[0m   File "/dist/ella-python/lib/python3.7/site-packages/sqlalchemy/orm/session.py", line 2404, in _flush
[36mella_1        |[0m     flush_context.execute()
[36mella_1        |[0m   File "/dist/ella-python/lib/python3.7/site-packages/sqlalchemy/orm/unitofwork.py", line 395, in execute
[36mella_1        |[0m     rec.execute(self)
[36mella_1        |[0m   File "/dist/ella-python/lib/python3.7/site-packages/sqlalchemy/orm/unitofwork.py", line 560, in execute
[36mella_1        |[0m     uow
[36mella_1        |[0m   File "/dist/ella-python/lib/python3.7/site-packages/sqlalchemy/orm/persistence.py", line 181, in save_obj
[36mella_1        |[0m     mapper, table, insert)
[36mella_1        |[0m   File "/dist/ella-python/lib/python3.7/site-packages/sqlalchemy/orm/persistence.py", line 872, in _emit_insert_statements
[36mella_1        |[0m     execute(statement, params)
[36mella_1        |[0m   File "/dist/ella-python/lib/python3.7/site-packages/sqlalchemy/engine/base.py", line 948, in execute
[36mella_1        |[0m     return meth(self, multiparams, params)
[36mella_1        |[0m   File "/dist/ella-python/lib/python3.7/site-packages/sqlalchemy/sql/elements.py", line 269, in _execute_on_connection
[36mella_1        |[0m     return connection._execute_clauseelement(self, multiparams, params)
[36mella_1        |[0m   File "/dist/ella-python/lib/python3.7/site-packages/sqlalchemy/engine/base.py", line 1060, in _execute_clauseelement
[36mella_1        |[0m     compiled_sql, distilled_params
[36mella_1        |[0m   File "/dist/ella-python/lib/python3.7/site-packages/sqlalchemy/engine/base.py", line 1200, in _execute_context
[36mella_1        |[0m     context)
[36mella_1        |[0m   File "/dist/ella-python/lib/python3.7/site-packages/sqlalchemy/engine/base.py", line 1409, in _handle_dbapi_exception
[36mella_1        |[0m     util.raise_from_cause(newraise, exc_info)
[36mella_1        |[0m   File "/dist/ella-python/lib/python3.7/site-packages/sqlalchemy/util/compat.py", line 265, in raise_from_cause
[36mella_1        |[0m     reraise(type(exception), exception, tb=exc_tb, cause=cause)
[36mella_1        |[0m   File "/dist/ella-python/lib/python3.7/site-packages/sqlalchemy/util/compat.py", line 248, in reraise
[36mella_1        |[0m     raise value.with_traceback(tb)
[36mella_1        |[0m   File "/dist/ella-python/lib/python3.7/site-packages/sqlalchemy/engine/base.py", line 1193, in _execute_context
[36mella_1        |[0m     context)
[36mella_1        |[0m   File "/dist/ella-python/lib/python3.7/site-packages/sqlalchemy/engine/default.py", line 509, in do_execute
[36mella_1        |[0m     cursor.execute(statement, parameters)
[36mella_1        |[0m psycopg2.ProgrammingError: relation "resourcelog" does not exist
[36mella_1        |[0m LINE 1: INSERT INTO resourcelog (remote_addr, time, duration, userse...
[36mella_1        |[0m                     ^
[36mella_1        |[0m 
[36mella_1        |[0m 2020-09-17 05:52:34,197 [INFO] werkzeug: 172.20.0.1 - - [17/Sep/2020 05:52:34] "GET /api/v1/broadcasts/ HTTP/1.1" 500 -
[36mella_1        |[0m 2020-09-17 06:12:06.899 UTC [233] ERROR:  relation "broadcast" does not exist at character 171
[36mella_1        |[0m 2020-09-17 06:12:06.899 UTC [233] STATEMENT:  SELECT broadcast.id AS broadcast_id, broadcast.date_created AS broadcast_date_created, broadcast.message AS broadcast_message, broadcast.active AS broadcast_active 
[36mella_1        |[0m 	FROM broadcast 
[36mella_1        |[0m 	WHERE broadcast.active IS true ORDER BY broadcast.date_created
[36mella_1        |[0m 2020-09-17 06:12:06,905 [ERROR] flask.app: Exception on /api/v1/broadcasts/ [GET]
[36mella_1        |[0m Traceback (most recent call last):
[36mella_1        |[0m   File "/dist/ella-python/lib/python3.7/site-packages/flask/app.py", line 1813, in full_dispatch_request
[36mella_1        |[0m     rv = self.dispatch_request()
[36mella_1        |[0m   File "/dist/ella-python/lib/python3.7/site-packages/flask/app.py", line 1799, in dispatch_request
[36mella_1        |[0m     return self.view_functions[rule.endpoint](**req.view_args)
[36mella_1        |[0m   File "/dist/ella-python/lib/python3.7/site-packages/flask_restful/__init__.py", line 458, in wrapper
[36mella_1        |[0m     resp = resource(*args, **kwargs)
[36mella_1        |[0m   File "/dist/ella-python/lib/python3.7/site-packages/flask/views.py", line 88, in view
[36mella_1        |[0m     return self.dispatch_request(*args, **kwargs)
[36mella_1        |[0m   File "/dist/ella-python/lib/python3.7/site-packages/flask_restful/__init__.py", line 573, in dispatch_request
[36mella_1        |[0m     resp = meth(*args, **kwargs)
[36mella_1        |[0m   File "/ella/src/api/util/util.py", line 229, in inner
[36mella_1        |[0m     return func(db.session, *args, **kwargs)
[36mella_1        |[0m   File "/ella/src/api/util/util.py", line 218, in inner
[36mella_1        |[0m     return func(*args, **kwargs)
[36mella_1        |[0m   File "/ella/src/api/util/util.py", line 435, in inner
[36mella_1        |[0m     return func(*args, **kwargs)
[36mella_1        |[0m   File "/ella/src/api/v1/resources/broadcast.py", line 56, in get
[36mella_1        |[0m     .order_by(broadcast.Broadcast.date_created)
[36mella_1        |[0m   File "/dist/ella-python/lib/python3.7/site-packages/sqlalchemy/orm/query.py", line 2843, in all
[36mella_1        |[0m     return list(self)
[36mella_1        |[0m   File "/dist/ella-python/lib/python3.7/site-packages/sqlalchemy/orm/query.py", line 2995, in __iter__
[36mella_1        |[0m     return self._execute_and_instances(context)
[36mella_1        |[0m   File "/dist/ella-python/lib/python3.7/site-packages/sqlalchemy/orm/query.py", line 3018, in _execute_and_instances
[36mella_1        |[0m     result = conn.execute(querycontext.statement, self._params)
[36mella_1        |[0m   File "/dist/ella-python/lib/python3.7/site-packages/sqlalchemy/engine/base.py", line 948, in execute
[36mella_1        |[0m     return meth(self, multiparams, params)
[36mella_1        |[0m   File "/dist/ella-python/lib/python3.7/site-packages/sqlalchemy/sql/elements.py", line 269, in _execute_on_connection
[36mella_1        |[0m     return connection._execute_clauseelement(self, multiparams, params)
[36mella_1        |[0m   File "/dist/ella-python/lib/python3.7/site-packages/sqlalchemy/engine/base.py", line 1060, in _execute_clauseelement
[36mella_1        |[0m     compiled_sql, distilled_params
[36mella_1        |[0m   File "/dist/ella-python/lib/python3.7/site-packages/sqlalchemy/engine/base.py", line 1200, in _execute_context
[36mella_1        |[0m     context)
[36mella_1        |[0m   File "/dist/ella-python/lib/python3.7/site-packages/sqlalchemy/engine/base.py", line 1409, in _handle_dbapi_exception
[36mella_1        |[0m     util.raise_from_cause(newraise, exc_info)
[36mella_1        |[0m   File "/dist/ella-python/lib/python3.7/site-packages/sqlalchemy/util/compat.py", line 265, in raise_from_cause
[36mella_1        |[0m     reraise(type(exception), exception, tb=exc_tb, cause=cause)
[36mella_1        |[0m   File "/dist/ella-python/lib/python3.7/site-packages/sqlalchemy/util/compat.py", line 248, in reraise
[36mella_1        |[0m     raise value.with_traceback(tb)
[36mella_1        |[0m   File "/dist/ella-python/lib/python3.7/site-packages/sqlalchemy/engine/base.py", line 1193, in _execute_context
[36mella_1        |[0m     context)
[36mella_1        |[0m   File "/dist/ella-python/lib/python3.7/site-packages/sqlalchemy/engine/default.py", line 509, in do_execute
[36mella_1        |[0m     cursor.execute(statement, parameters)
[36mella_1        |[0m psycopg2.ProgrammingError: relation "broadcast" does not exist
[36mella_1        |[0m LINE 2: FROM broadcast 
[36mella_1        |[0m              ^
[36mella_1        |[0m 
[36mella_1        |[0m 2020-09-17 06:12:06.913 UTC [233] ERROR:  relation "resourcelog" does not exist at character 13
[36mella_1        |[0m 2020-09-17 06:12:06.913 UTC [233] STATEMENT:  INSERT INTO resourcelog (remote_addr, time, duration, usersession_id, method, resource, query, response, response_size, payload, payload_size, statuscode) VALUES ('172.20.0.1', '2020-09-17T06:12:06.912813+00:00'::timestamptz, 40, NULL, 'GET', '/api/v1/broadcasts/', '', NULL, 36, NULL, 0, 500) RETURNING resourcelog.id
[36mella_1        |[0m 2020-09-17 06:12:06,914 [ERROR] flask.app: Something went wrong when commiting resourcelog entry
[36mella_1        |[0m Traceback (most recent call last):
[36mella_1        |[0m   File "/ella/src/api/main.py", line 47, in after_request
[36mella_1        |[0m     db.session.commit()
[36mella_1        |[0m   File "/dist/ella-python/lib/python3.7/site-packages/sqlalchemy/orm/scoping.py", line 153, in do
[36mella_1        |[0m     return getattr(self.registry(), name)(*args, **kwargs)
[36mella_1        |[0m   File "/dist/ella-python/lib/python3.7/site-packages/sqlalchemy/orm/session.py", line 954, in commit
[36mella_1        |[0m     self.transaction.commit()
[36mella_1        |[0m   File "/dist/ella-python/lib/python3.7/site-packages/sqlalchemy/orm/session.py", line 467, in commit
[36mella_1        |[0m     self._prepare_impl()
[36mella_1        |[0m   File "/dist/ella-python/lib/python3.7/site-packages/sqlalchemy/orm/session.py", line 447, in _prepare_impl
[36mella_1        |[0m     self.session.flush()
[36mella_1        |[0m   File "/dist/ella-python/lib/python3.7/site-packages/sqlalchemy/orm/session.py", line 2313, in flush
[36mella_1        |[0m     self._flush(objects)
[36mella_1        |[0m   File "/dist/ella-python/lib/python3.7/site-packages/sqlalchemy/orm/session.py", line 2440, in _flush
[36mella_1        |[0m     transaction.rollback(_capture_exception=True)
[36mella_1        |[0m   File "/dist/ella-python/lib/python3.7/site-packages/sqlalchemy/util/langhelpers.py", line 66, in __exit__
[36mella_1        |[0m     compat.reraise(exc_type, exc_value, exc_tb)
[36mella_1        |[0m   File "/dist/ella-python/lib/python3.7/site-packages/sqlalchemy/util/compat.py", line 249, in reraise
[36mella_1        |[0m     raise value
[36mella_1        |[0m   File "/dist/ella-python/lib/python3.7/site-packages/sqlalchemy/orm/session.py", line 2404, in _flush
[36mella_1        |[0m     flush_context.execute()
[36mella_1        |[0m   File "/dist/ella-python/lib/python3.7/site-packages/sqlalchemy/orm/unitofwork.py", line 395, in execute
[36mella_1        |[0m     rec.execute(self)
[36mella_1        |[0m   File "/dist/ella-python/lib/python3.7/site-packages/sqlalchemy/orm/unitofwork.py", line 560, in execute
[36mella_1        |[0m     uow
[36mella_1        |[0m   File "/dist/ella-python/lib/python3.7/site-packages/sqlalchemy/orm/persistence.py", line 181, in save_obj
[36mella_1        |[0m     mapper, table, insert)
[36mella_1        |[0m   File "/dist/ella-python/lib/python3.7/site-packages/sqlalchemy/orm/persistence.py", line 872, in _emit_insert_statements
[36mella_1        |[0m     execute(statement, params)
[36mella_1        |[0m   File "/dist/ella-python/lib/python3.7/site-packages/sqlalchemy/engine/base.py", line 948, in execute
[36mella_1        |[0m     return meth(self, multiparams, params)
[36mella_1        |[0m   File "/dist/ella-python/lib/python3.7/site-packages/sqlalchemy/sql/elements.py", line 269, in _execute_on_connection
[36mella_1        |[0m     return connection._execute_clauseelement(self, multiparams, params)
[36mella_1        |[0m   File "/dist/ella-python/lib/python3.7/site-packages/sqlalchemy/engine/base.py", line 1060, in _execute_clauseelement
[36mella_1        |[0m     compiled_sql, distilled_params
[36mella_1        |[0m   File "/dist/ella-python/lib/python3.7/site-packages/sqlalchemy/engine/base.py", line 1200, in _execute_context
[36mella_1        |[0m     context)
[36mella_1        |[0m   File "/dist/ella-python/lib/python3.7/site-packages/sqlalchemy/engine/base.py", line 1409, in _handle_dbapi_exception
[36mella_1        |[0m     util.raise_from_cause(newraise, exc_info)
[36mella_1        |[0m   File "/dist/ella-python/lib/python3.7/site-packages/sqlalchemy/util/compat.py", line 265, in raise_from_cause
[36mella_1        |[0m     reraise(type(exception), exception, tb=exc_tb, cause=cause)
[36mella_1        |[0m   File "/dist/ella-python/lib/python3.7/site-packages/sqlalchemy/util/compat.py", line 248, in reraise
[36mella_1        |[0m     raise value.with_traceback(tb)
[36mella_1        |[0m   File "/dist/ella-python/lib/python3.7/site-packages/sqlalchemy/engine/base.py", line 1193, in _execute_context
[36mella_1        |[0m     context)
[36mella_1        |[0m   File "/dist/ella-python/lib/python3.7/site-packages/sqlalchemy/engine/default.py", line 509, in do_execute
[36mella_1        |[0m     cursor.execute(statement, parameters)
[36mella_1        |[0m psycopg2.ProgrammingError: relation "resourcelog" does not exist
[36mella_1        |[0m LINE 1: INSERT INTO resourcelog (remote_addr, time, duration, userse...
[36mella_1        |[0m                     ^
[36mella_1        |[0m 
[36mella_1        |[0m 2020-09-17 06:12:06,917 [INFO] werkzeug: 172.20.0.1 - - [17/Sep/2020 06:12:06] "GET /api/v1/broadcasts/ HTTP/1.1" 500 -
[36mella_1        |[0m 2020-09-17 06:22:06.839 UTC [233] ERROR:  relation "broadcast" does not exist at character 171
[36mella_1        |[0m 2020-09-17 06:22:06.839 UTC [233] STATEMENT:  SELECT broadcast.id AS broadcast_id, broadcast.date_created AS broadcast_date_created, broadcast.message AS broadcast_message, broadcast.active AS broadcast_active 
[36mella_1        |[0m 	FROM broadcast 
[36mella_1        |[0m 	WHERE broadcast.active IS true ORDER BY broadcast.date_created
[36mella_1        |[0m 2020-09-17 06:22:06,842 [ERROR] flask.app: Exception on /api/v1/broadcasts/ [GET]
[36mella_1        |[0m Traceback (most recent call last):
[36mella_1        |[0m   File "/dist/ella-python/lib/python3.7/site-packages/flask/app.py", line 1813, in full_dispatch_request
[36mella_1        |[0m     rv = self.dispatch_request()
[36mella_1        |[0m   File "/dist/ella-python/lib/python3.7/site-packages/flask/app.py", line 1799, in dispatch_request
[36mella_1        |[0m     return self.view_functions[rule.endpoint](**req.view_args)
[36mella_1        |[0m   File "/dist/ella-python/lib/python3.7/site-packages/flask_restful/__init__.py", line 458, in wrapper
[36mella_1        |[0m     resp = resource(*args, **kwargs)
[36mella_1        |[0m   File "/dist/ella-python/lib/python3.7/site-packages/flask/views.py", line 88, in view
[36mella_1        |[0m     return self.dispatch_request(*args, **kwargs)
[36mella_1        |[0m   File "/dist/ella-python/lib/python3.7/site-packages/flask_restful/__init__.py", line 573, in dispatch_request
[36mella_1        |[0m     resp = meth(*args, **kwargs)
[36mella_1        |[0m   File "/ella/src/api/util/util.py", line 229, in inner
[36mella_1        |[0m     return func(db.session, *args, **kwargs)
[36mella_1        |[0m   File "/ella/src/api/util/util.py", line 218, in inner
[36mella_1        |[0m     return func(*args, **kwargs)
[36mella_1        |[0m   File "/ella/src/api/util/util.py", line 435, in inner
[36mella_1        |[0m     return func(*args, **kwargs)
[36mella_1        |[0m   File "/ella/src/api/v1/resources/broadcast.py", line 56, in get
[36mella_1        |[0m     .order_by(broadcast.Broadcast.date_created)
[36mella_1        |[0m   File "/dist/ella-python/lib/python3.7/site-packages/sqlalchemy/orm/query.py", line 2843, in all
[36mella_1        |[0m     return list(self)
[36mella_1        |[0m   File "/dist/ella-python/lib/python3.7/site-packages/sqlalchemy/orm/query.py", line 2995, in __iter__
[36mella_1        |[0m     return self._execute_and_instances(context)
[36mella_1        |[0m   File "/dist/ella-python/lib/python3.7/site-packages/sqlalchemy/orm/query.py", line 3018, in _execute_and_instances
[36mella_1        |[0m     result = conn.execute(querycontext.statement, self._params)
[36mella_1        |[0m   File "/dist/ella-python/lib/python3.7/site-packages/sqlalchemy/engine/base.py", line 948, in execute
[36mella_1        |[0m     return meth(self, multiparams, params)
[36mella_1        |[0m   File "/dist/ella-python/lib/python3.7/site-packages/sqlalchemy/sql/elements.py", line 269, in _execute_on_connection
[36mella_1        |[0m     return connection._execute_clauseelement(self, multiparams, params)
[36mella_1        |[0m   File "/dist/ella-python/lib/python3.7/site-packages/sqlalchemy/engine/base.py", line 1060, in _execute_clauseelement
[36mella_1        |[0m     compiled_sql, distilled_params
[36mella_1        |[0m   File "/dist/ella-python/lib/python3.7/site-packages/sqlalchemy/engine/base.py", line 1200, in _execute_context
[36mella_1        |[0m     context)
[36mella_1        |[0m   File "/dist/ella-python/lib/python3.7/site-packages/sqlalchemy/engine/base.py", line 1409, in _handle_dbapi_exception
[36mella_1        |[0m     util.raise_from_cause(newraise, exc_info)
[36mella_1        |[0m   File "/dist/ella-python/lib/python3.7/site-packages/sqlalchemy/util/compat.py", line 265, in raise_from_cause
[36mella_1        |[0m     reraise(type(exception), exception, tb=exc_tb, cause=cause)
[36mella_1        |[0m   File "/dist/ella-python/lib/python3.7/site-packages/sqlalchemy/util/compat.py", line 248, in reraise
[36mella_1        |[0m     raise value.with_traceback(tb)
[36mella_1        |[0m   File "/dist/ella-python/lib/python3.7/site-packages/sqlalchemy/engine/base.py", line 1193, in _execute_context
[36mella_1        |[0m     context)
[36mella_1        |[0m   File "/dist/ella-python/lib/python3.7/site-packages/sqlalchemy/engine/default.py", line 509, in do_execute
[36mella_1        |[0m     cursor.execute(statement, parameters)
[36mella_1        |[0m psycopg2.ProgrammingError: relation "broadcast" does not exist
[36mella_1        |[0m LINE 2: FROM broadcast 
[36mella_1        |[0m              ^
[36mella_1        |[0m 
[36mella_1        |[0m 2020-09-17 06:22:06.850 UTC [233] ERROR:  relation "resourcelog" does not exist at character 13
[36mella_1        |[0m 2020-09-17 06:22:06.850 UTC [233] STATEMENT:  INSERT INTO resourcelog (remote_addr, time, duration, usersession_id, method, resource, query, response, response_size, payload, payload_size, statuscode) VALUES ('172.20.0.1', '2020-09-17T06:22:06.849419+00:00'::timestamptz, 14, NULL, 'GET', '/api/v1/broadcasts/', '', NULL, 36, NULL, 0, 500) RETURNING resourcelog.id
[36mella_1        |[0m 2020-09-17 06:22:06,853 [ERROR] flask.app: Something went wrong when commiting resourcelog entry
[36mella_1        |[0m Traceback (most recent call last):
[36mella_1        |[0m   File "/ella/src/api/main.py", line 47, in after_request
[36mella_1        |[0m     db.session.commit()
[36mella_1        |[0m   File "/dist/ella-python/lib/python3.7/site-packages/sqlalchemy/orm/scoping.py", line 153, in do
[36mella_1        |[0m     return getattr(self.registry(), name)(*args, **kwargs)
[36mella_1        |[0m   File "/dist/ella-python/lib/python3.7/site-packages/sqlalchemy/orm/session.py", line 954, in commit
[36mella_1        |[0m     self.transaction.commit()
[36mella_1        |[0m   File "/dist/ella-python/lib/python3.7/site-packages/sqlalchemy/orm/session.py", line 467, in commit
[36mella_1        |[0m     self._prepare_impl()
[36mella_1        |[0m   File "/dist/ella-python/lib/python3.7/site-packages/sqlalchemy/orm/session.py", line 447, in _prepare_impl
[36mella_1        |[0m     self.session.flush()
[36mella_1        |[0m   File "/dist/ella-python/lib/python3.7/site-packages/sqlalchemy/orm/session.py", line 2313, in flush
[36mella_1        |[0m     self._flush(objects)
[36mella_1        |[0m   File "/dist/ella-python/lib/python3.7/site-packages/sqlalchemy/orm/session.py", line 2440, in _flush
[36mella_1        |[0m     transaction.rollback(_capture_exception=True)
[36mella_1        |[0m   File "/dist/ella-python/lib/python3.7/site-packages/sqlalchemy/util/langhelpers.py", line 66, in __exit__
[36mella_1        |[0m     compat.reraise(exc_type, exc_value, exc_tb)
[36mella_1        |[0m   File "/dist/ella-python/lib/python3.7/site-packages/sqlalchemy/util/compat.py", line 249, in reraise
[36mella_1        |[0m     raise value
[36mella_1        |[0m   File "/dist/ella-python/lib/python3.7/site-packages/sqlalchemy/orm/session.py", line 2404, in _flush
[36mella_1        |[0m     flush_context.execute()
[36mella_1        |[0m   File "/dist/ella-python/lib/python3.7/site-packages/sqlalchemy/orm/unitofwork.py", line 395, in execute
[36mella_1        |[0m     rec.execute(self)
[36mella_1        |[0m   File "/dist/ella-python/lib/python3.7/site-packages/sqlalchemy/orm/unitofwork.py", line 560, in execute
[36mella_1        |[0m     uow
[36mella_1        |[0m   File "/dist/ella-python/lib/python3.7/site-packages/sqlalchemy/orm/persistence.py", line 181, in save_obj
[36mella_1        |[0m     mapper, table, insert)
[36mella_1        |[0m   File "/dist/ella-python/lib/python3.7/site-packages/sqlalchemy/orm/persistence.py", line 872, in _emit_insert_statements
[36mella_1        |[0m     execute(statement, params)
[36mella_1        |[0m   File "/dist/ella-python/lib/python3.7/site-packages/sqlalchemy/engine/base.py", line 948, in execute
[36mella_1        |[0m     return meth(self, multiparams, params)
[36mella_1        |[0m   File "/dist/ella-python/lib/python3.7/site-packages/sqlalchemy/sql/elements.py", line 269, in _execute_on_connection
[36mella_1        |[0m     return connection._execute_clauseelement(self, multiparams, params)
[36mella_1        |[0m   File "/dist/ella-python/lib/python3.7/site-packages/sqlalchemy/engine/base.py", line 1060, in _execute_clauseelement
[36mella_1        |[0m     compiled_sql, distilled_params
[36mella_1        |[0m   File "/dist/ella-python/lib/python3.7/site-packages/sqlalchemy/engine/base.py", line 1200, in _execute_context
[36mella_1        |[0m     context)
[36mella_1        |[0m   File "/dist/ella-python/lib/python3.7/site-packages/sqlalchemy/engine/base.py", line 1409, in _handle_dbapi_exception
[36mella_1        |[0m     util.raise_from_cause(newraise, exc_info)
[36mella_1        |[0m   File "/dist/ella-python/lib/python3.7/site-packages/sqlalchemy/util/compat.py", line 265, in raise_from_cause
[36mella_1        |[0m     reraise(type(exception), exception, tb=exc_tb, cause=cause)
[36mella_1        |[0m   File "/dist/ella-python/lib/python3.7/site-packages/sqlalchemy/util/compat.py", line 248, in reraise
[36mella_1        |[0m     raise value.with_traceback(tb)
[36mella_1        |[0m   File "/dist/ella-python/lib/python3.7/site-packages/sqlalchemy/engine/base.py", line 1193, in _execute_context
[36mella_1        |[0m     context)
[36mella_1        |[0m   File "/dist/ella-python/lib/python3.7/site-packages/sqlalchemy/engine/default.py", line 509, in do_execute
[36mella_1        |[0m     cursor.execute(statement, parameters)
[36mella_1        |[0m psycopg2.ProgrammingError: relation "resourcelog" does not exist
[36mella_1        |[0m LINE 1: INSERT INTO resourcelog (remote_addr, time, duration, userse...
[36mella_1        |[0m                     ^
[36mella_1        |[0m 
[36mella_1        |[0m 2020-09-17 06:22:06,859 [INFO] werkzeug: 172.20.0.1 - - [17/Sep/2020 06:22:06] "GET /api/v1/broadcasts/ HTTP/1.1" 500 -
[36mella_1        |[0m 2020-09-17 06:32:06.790 UTC [233] ERROR:  relation "broadcast" does not exist at character 171
[36mella_1        |[0m 2020-09-17 06:32:06.790 UTC [233] STATEMENT:  SELECT broadcast.id AS broadcast_id, broadcast.date_created AS broadcast_date_created, broadcast.message AS broadcast_message, broadcast.active AS broadcast_active 
[36mella_1        |[0m 	FROM broadcast 
[36mella_1        |[0m 	WHERE broadcast.active IS true ORDER BY broadcast.date_created
[36mella_1        |[0m 2020-09-17 06:32:06,792 [ERROR] flask.app: Exception on /api/v1/broadcasts/ [GET]
[36mella_1        |[0m Traceback (most recent call last):
[36mella_1        |[0m   File "/dist/ella-python/lib/python3.7/site-packages/flask/app.py", line 1813, in full_dispatch_request
[36mella_1        |[0m     rv = self.dispatch_request()
[36mella_1        |[0m   File "/dist/ella-python/lib/python3.7/site-packages/flask/app.py", line 1799, in dispatch_request
[36mella_1        |[0m     return self.view_functions[rule.endpoint](**req.view_args)
[36mella_1        |[0m   File "/dist/ella-python/lib/python3.7/site-packages/flask_restful/__init__.py", line 458, in wrapper
[36mella_1        |[0m     resp = resource(*args, **kwargs)
[36mella_1        |[0m   File "/dist/ella-python/lib/python3.7/site-packages/flask/views.py", line 88, in view
[36mella_1        |[0m     return self.dispatch_request(*args, **kwargs)
[36mella_1        |[0m   File "/dist/ella-python/lib/python3.7/site-packages/flask_restful/__init__.py", line 573, in dispatch_request
[36mella_1        |[0m     resp = meth(*args, **kwargs)
[36mella_1        |[0m   File "/ella/src/api/util/util.py", line 229, in inner
[36mella_1        |[0m     return func(db.session, *args, **kwargs)
[36mella_1        |[0m   File "/ella/src/api/util/util.py", line 218, in inner
[36mella_1        |[0m     return func(*args, **kwargs)
[36mella_1        |[0m   File "/ella/src/api/util/util.py", line 435, in inner
[36mella_1        |[0m     return func(*args, **kwargs)
[36mella_1        |[0m   File "/ella/src/api/v1/resources/broadcast.py", line 56, in get
[36mella_1        |[0m     .order_by(broadcast.Broadcast.date_created)
[36mella_1        |[0m   File "/dist/ella-python/lib/python3.7/site-packages/sqlalchemy/orm/query.py", line 2843, in all
[36mella_1        |[0m     return list(self)
[36mella_1        |[0m   File "/dist/ella-python/lib/python3.7/site-packages/sqlalchemy/orm/query.py", line 2995, in __iter__
[36mella_1        |[0m     return self._execute_and_instances(context)
[36mella_1        |[0m   File "/dist/ella-python/lib/python3.7/site-packages/sqlalchemy/orm/query.py", line 3018, in _execute_and_instances
[36mella_1        |[0m     result = conn.execute(querycontext.statement, self._params)
[36mella_1        |[0m   File "/dist/ella-python/lib/python3.7/site-packages/sqlalchemy/engine/base.py", line 948, in execute
[36mella_1        |[0m     return meth(self, multiparams, params)
[36mella_1        |[0m   File "/dist/ella-python/lib/python3.7/site-packages/sqlalchemy/sql/elements.py", line 269, in _execute_on_connection
[36mella_1        |[0m     return connection._execute_clauseelement(self, multiparams, params)
[36mella_1        |[0m   File "/dist/ella-python/lib/python3.7/site-packages/sqlalchemy/engine/base.py", line 1060, in _execute_clauseelement
[36mella_1        |[0m     compiled_sql, distilled_params
[36mella_1        |[0m   File "/dist/ella-python/lib/python3.7/site-packages/sqlalchemy/engine/base.py", line 1200, in _execute_context
[36mella_1        |[0m     context)
[36mella_1        |[0m   File "/dist/ella-python/lib/python3.7/site-packages/sqlalchemy/engine/base.py", line 1409, in _handle_dbapi_exception
[36mella_1        |[0m     util.raise_from_cause(newraise, exc_info)
[36mella_1        |[0m   File "/dist/ella-python/lib/python3.7/site-packages/sqlalchemy/util/compat.py", line 265, in raise_from_cause
[36mella_1        |[0m     reraise(type(exception), exception, tb=exc_tb, cause=cause)
[36mella_1        |[0m   File "/dist/ella-python/lib/python3.7/site-packages/sqlalchemy/util/compat.py", line 248, in reraise
[36mella_1        |[0m     raise value.with_traceback(tb)
[36mella_1        |[0m   File "/dist/ella-python/lib/python3.7/site-packages/sqlalchemy/engine/base.py", line 1193, in _execute_context
[36mella_1        |[0m     context)
[36mella_1        |[0m   File "/dist/ella-python/lib/python3.7/site-packages/sqlalchemy/engine/default.py", line 509, in do_execute
[36mella_1        |[0m     cursor.execute(statement, parameters)
[36mella_1        |[0m psycopg2.ProgrammingError: relation "broadcast" does not exist
[36mella_1        |[0m LINE 2: FROM broadcast 
[36mella_1        |[0m              ^
[36mella_1        |[0m 
[36mella_1        |[0m 2020-09-17 06:32:06.798 UTC [233] ERROR:  relation "resourcelog" does not exist at character 13
[36mella_1        |[0m 2020-09-17 06:32:06.798 UTC [233] STATEMENT:  INSERT INTO resourcelog (remote_addr, time, duration, usersession_id, method, resource, query, response, response_size, payload, payload_size, statuscode) VALUES ('172.20.0.1', '2020-09-17T06:32:06.797251+00:00'::timestamptz, 7, NULL, 'GET', '/api/v1/broadcasts/', '', NULL, 36, NULL, 0, 500) RETURNING resourcelog.id
[36mella_1        |[0m 2020-09-17 06:32:06,799 [ERROR] flask.app: Something went wrong when commiting resourcelog entry
[36mella_1        |[0m Traceback (most recent call last):
[36mella_1        |[0m   File "/ella/src/api/main.py", line 47, in after_request
[36mella_1        |[0m     db.session.commit()
[36mella_1        |[0m   File "/dist/ella-python/lib/python3.7/site-packages/sqlalchemy/orm/scoping.py", line 153, in do
[36mella_1        |[0m     return getattr(self.registry(), name)(*args, **kwargs)
[36mella_1        |[0m   File "/dist/ella-python/lib/python3.7/site-packages/sqlalchemy/orm/session.py", line 954, in commit
[36mella_1        |[0m     self.transaction.commit()
[36mella_1        |[0m   File "/dist/ella-python/lib/python3.7/site-packages/sqlalchemy/orm/session.py", line 467, in commit
[36mella_1        |[0m     self._prepare_impl()
[36mella_1        |[0m   File "/dist/ella-python/lib/python3.7/site-packages/sqlalchemy/orm/session.py", line 447, in _prepare_impl
[36mella_1        |[0m     self.session.flush()
[36mella_1        |[0m   File "/dist/ella-python/lib/python3.7/site-packages/sqlalchemy/orm/session.py", line 2313, in flush
[36mella_1        |[0m     self._flush(objects)
[36mella_1        |[0m   File "/dist/ella-python/lib/python3.7/site-packages/sqlalchemy/orm/session.py", line 2440, in _flush
[36mella_1        |[0m     transaction.rollback(_capture_exception=True)
[36mella_1        |[0m   File "/dist/ella-python/lib/python3.7/site-packages/sqlalchemy/util/langhelpers.py", line 66, in __exit__
[36mella_1        |[0m     compat.reraise(exc_type, exc_value, exc_tb)
[36mella_1        |[0m   File "/dist/ella-python/lib/python3.7/site-packages/sqlalchemy/util/compat.py", line 249, in reraise
[36mella_1        |[0m     raise value
[36mella_1        |[0m   File "/dist/ella-python/lib/python3.7/site-packages/sqlalchemy/orm/session.py", line 2404, in _flush
[36mella_1        |[0m     flush_context.execute()
[36mella_1        |[0m   File "/dist/ella-python/lib/python3.7/site-packages/sqlalchemy/orm/unitofwork.py", line 395, in execute
[36mella_1        |[0m     rec.execute(self)
[36mella_1        |[0m   File "/dist/ella-python/lib/python3.7/site-packages/sqlalchemy/orm/unitofwork.py", line 560, in execute
[36mella_1        |[0m     uow
[36mella_1        |[0m   File "/dist/ella-python/lib/python3.7/site-packages/sqlalchemy/orm/persistence.py", line 181, in save_obj
[36mella_1        |[0m     mapper, table, insert)
[36mella_1        |[0m   File "/dist/ella-python/lib/python3.7/site-packages/sqlalchemy/orm/persistence.py", line 872, in _emit_insert_statements
[36mella_1        |[0m     execute(statement, params)
[36mella_1        |[0m   File "/dist/ella-python/lib/python3.7/site-packages/sqlalchemy/engine/base.py", line 948, in execute
[36mella_1        |[0m     return meth(self, multiparams, params)
[36mella_1        |[0m   File "/dist/ella-python/lib/python3.7/site-packages/sqlalchemy/sql/elements.py", line 269, in _execute_on_connection
[36mella_1        |[0m     return connection._execute_clauseelement(self, multiparams, params)
[36mella_1        |[0m   File "/dist/ella-python/lib/python3.7/site-packages/sqlalchemy/engine/base.py", line 1060, in _execute_clauseelement
[36mella_1        |[0m     compiled_sql, distilled_params
[36mella_1        |[0m   File "/dist/ella-python/lib/python3.7/site-packages/sqlalchemy/engine/base.py", line 1200, in _execute_context
[36mella_1        |[0m     context)
[36mella_1        |[0m   File "/dist/ella-python/lib/python3.7/site-packages/sqlalchemy/engine/base.py", line 1409, in _handle_dbapi_exception
[36mella_1        |[0m     util.raise_from_cause(newraise, exc_info)
[36mella_1        |[0m   File "/dist/ella-python/lib/python3.7/site-packages/sqlalchemy/util/compat.py", line 265, in raise_from_cause
[36mella_1        |[0m     reraise(type(exception), exception, tb=exc_tb, cause=cause)
[36mella_1        |[0m   File "/dist/ella-python/lib/python3.7/site-packages/sqlalchemy/util/compat.py", line 248, in reraise
[36mella_1        |[0m     raise value.with_traceback(tb)
[36mella_1        |[0m   File "/dist/ella-python/lib/python3.7/site-packages/sqlalchemy/engine/base.py", line 1193, in _execute_context
[36mella_1        |[0m     context)
[36mella_1        |[0m   File "/dist/ella-python/lib/python3.7/site-packages/sqlalchemy/engine/default.py", line 509, in do_execute
[36mella_1        |[0m     cursor.execute(statement, parameters)
[36mella_1        |[0m psycopg2.ProgrammingError: relation "resourcelog" does not exist
[36mella_1        |[0m LINE 1: INSERT INTO resourcelog (remote_addr, time, duration, userse...
[36mella_1        |[0m                     ^
[36mella_1        |[0m 
[36mella_1        |[0m 2020-09-17 06:32:06,801 [INFO] werkzeug: 172.20.0.1 - - [17/Sep/2020 06:32:06] "GET /api/v1/broadcasts/ HTTP/1.1" 500 -
[36mella_1        |[0m 2020-09-17 06:40:20.369 UTC [233] ERROR:  relation "resourcelog" does not exist at character 13
[36mella_1        |[0m 2020-09-17 06:40:20.369 UTC [233] STATEMENT:  INSERT INTO resourcelog (remote_addr, time, duration, usersession_id, method, resource, query, response, response_size, payload, payload_size, statuscode) VALUES ('172.20.0.1', '2020-09-17T06:40:20.368536+00:00'::timestamptz, 13, NULL, 'GET', '/login', '', NULL, 578, NULL, 0, 200) RETURNING resourcelog.id
[36mella_1        |[0m 2020-09-17 06:40:20,371 [ERROR] flask.app: Something went wrong when commiting resourcelog entry
[36mella_1        |[0m Traceback (most recent call last):
[36mella_1        |[0m   File "/ella/src/api/main.py", line 47, in after_request
[36mella_1        |[0m     db.session.commit()
[36mella_1        |[0m   File "/dist/ella-python/lib/python3.7/site-packages/sqlalchemy/orm/scoping.py", line 153, in do
[36mella_1        |[0m     return getattr(self.registry(), name)(*args, **kwargs)
[36mella_1        |[0m   File "/dist/ella-python/lib/python3.7/site-packages/sqlalchemy/orm/session.py", line 954, in commit
[36mella_1        |[0m     self.transaction.commit()
[36mella_1        |[0m   File "/dist/ella-python/lib/python3.7/site-packages/sqlalchemy/orm/session.py", line 467, in commit
[36mella_1        |[0m     self._prepare_impl()
[36mella_1        |[0m   File "/dist/ella-python/lib/python3.7/site-packages/sqlalchemy/orm/session.py", line 447, in _prepare_impl
[36mella_1        |[0m     self.session.flush()
[36mella_1        |[0m   File "/dist/ella-python/lib/python3.7/site-packages/sqlalchemy/orm/session.py", line 2313, in flush
[36mella_1        |[0m     self._flush(objects)
[36mella_1        |[0m   File "/dist/ella-python/lib/python3.7/site-packages/sqlalchemy/orm/session.py", line 2440, in _flush
[36mella_1        |[0m     transaction.rollback(_capture_exception=True)
[36mella_1        |[0m   File "/dist/ella-python/lib/python3.7/site-packages/sqlalchemy/util/langhelpers.py", line 66, in __exit__
[36mella_1        |[0m     compat.reraise(exc_type, exc_value, exc_tb)
[36mella_1        |[0m   File "/dist/ella-python/lib/python3.7/site-packages/sqlalchemy/util/compat.py", line 249, in reraise
[36mella_1        |[0m     raise value
[36mella_1        |[0m   File "/dist/ella-python/lib/python3.7/site-packages/sqlalchemy/orm/session.py", line 2404, in _flush
[36mella_1        |[0m     flush_context.execute()
[36mella_1        |[0m   File "/dist/ella-python/lib/python3.7/site-packages/sqlalchemy/orm/unitofwork.py", line 395, in execute
[36mella_1        |[0m     rec.execute(self)
[36mella_1        |[0m   File "/dist/ella-python/lib/python3.7/site-packages/sqlalchemy/orm/unitofwork.py", line 560, in execute
[36mella_1        |[0m     uow
[36mella_1        |[0m   File "/dist/ella-python/lib/python3.7/site-packages/sqlalchemy/orm/persistence.py", line 181, in save_obj
[36mella_1        |[0m     mapper, table, insert)
[36mella_1        |[0m   File "/dist/ella-python/lib/python3.7/site-packages/sqlalchemy/orm/persistence.py", line 872, in _emit_insert_statements
[36mella_1        |[0m     execute(statement, params)
[36mella_1        |[0m   File "/dist/ella-python/lib/python3.7/site-packages/sqlalchemy/engine/base.py", line 948, in execute
[36mella_1        |[0m     return meth(self, multiparams, params)
[36mella_1        |[0m   File "/dist/ella-python/lib/python3.7/site-packages/sqlalchemy/sql/elements.py", line 269, in _execute_on_connection
[36mella_1        |[0m     return connection._execute_clauseelement(self, multiparams, params)
[36mella_1        |[0m   File "/dist/ella-python/lib/python3.7/site-packages/sqlalchemy/engine/base.py", line 1060, in _execute_clauseelement
[36mella_1        |[0m     compiled_sql, distilled_params
[36mella_1        |[0m   File "/dist/ella-python/lib/python3.7/site-packages/sqlalchemy/engine/base.py", line 1200, in _execute_context
[36mella_1        |[0m     context)
[36mella_1        |[0m   File "/dist/ella-python/lib/python3.7/site-packages/sqlalchemy/engine/base.py", line 1409, in _handle_dbapi_exception
[36mella_1        |[0m     util.raise_from_cause(newraise, exc_info)
[36mella_1        |[0m   File "/dist/ella-python/lib/python3.7/site-packages/sqlalchemy/util/compat.py", line 265, in raise_from_cause
[36mella_1        |[0m     reraise(type(exception), exception, tb=exc_tb, cause=cause)
[36mella_1        |[0m   File "/dist/ella-python/lib/python3.7/site-packages/sqlalchemy/util/compat.py", line 248, in reraise
[36mella_1        |[0m     raise value.with_traceback(tb)
[36mella_1        |[0m   File "/dist/ella-python/lib/python3.7/site-packages/sqlalchemy/engine/base.py", line 1193, in _execute_context
[36mella_1        |[0m     context)
[36mella_1        |[0m   File "/dist/ella-python/lib/python3.7/site-packages/sqlalchemy/engine/default.py", line 509, in do_execute
[36mella_1        |[0m     cursor.execute(statement, parameters)
[36mella_1        |[0m psycopg2.ProgrammingError: relation "resourcelog" does not exist
[36mella_1        |[0m LINE 1: INSERT INTO resourcelog (remote_addr, time, duration, userse...
[36mella_1        |[0m                     ^
[36mella_1        |[0m 
[36mella_1        |[0m 2020-09-17 06:40:20,372 [INFO] werkzeug: 172.20.0.1 - - [17/Sep/2020 06:40:20] "GET /login HTTP/1.1" 200 -
[36mella_1        |[0m 2020-09-17 06:40:20,515 [INFO] werkzeug: 172.20.0.1 - - [17/Sep/2020 06:40:20] "GET /app.js HTTP/1.1" 200 -
[36mella_1        |[0m 2020-09-17 06:40:20,521 [INFO] werkzeug: 172.20.0.1 - - [17/Sep/2020 06:40:20] "GET /app.css HTTP/1.1" 200 -
[36mella_1        |[0m 2020-09-17 06:40:22,475 [INFO] werkzeug: 172.20.0.1 - - [17/Sep/2020 06:40:22] "GET /fonts/WorkSans-Regular.woff2 HTTP/1.1" 200 -
[36mella_1        |[0m 2020-09-17 06:40:22.547 UTC [233] ERROR:  relation "resourcelog" does not exist at character 13
[36mella_1        |[0m 2020-09-17 06:40:22.547 UTC [233] STATEMENT:  INSERT INTO resourcelog (remote_addr, time, duration, usersession_id, method, resource, query, response, response_size, payload, payload_size, statuscode) VALUES ('172.20.0.1', '2020-09-17T06:40:22.546859+00:00'::timestamptz, 120, NULL, 'GET', '/api/v1/config/', '', NULL, 60086, NULL, 0, 200) RETURNING resourcelog.id
[36mella_1        |[0m 2020-09-17 06:40:22,551 [ERROR] flask.app: Something went wrong when commiting resourcelog entry
[36mella_1        |[0m Traceback (most recent call last):
[36mella_1        |[0m   File "/ella/src/api/main.py", line 47, in after_request
[36mella_1        |[0m     db.session.commit()
[36mella_1        |[0m   File "/dist/ella-python/lib/python3.7/site-packages/sqlalchemy/orm/scoping.py", line 153, in do
[36mella_1        |[0m     return getattr(self.registry(), name)(*args, **kwargs)
[36mella_1        |[0m   File "/dist/ella-python/lib/python3.7/site-packages/sqlalchemy/orm/session.py", line 954, in commit
[36mella_1        |[0m     self.transaction.commit()
[36mella_1        |[0m   File "/dist/ella-python/lib/python3.7/site-packages/sqlalchemy/orm/session.py", line 467, in commit
[36mella_1        |[0m     self._prepare_impl()
[36mella_1        |[0m   File "/dist/ella-python/lib/python3.7/site-packages/sqlalchemy/orm/session.py", line 447, in _prepare_impl
[36mella_1        |[0m     self.session.flush()
[36mella_1        |[0m   File "/dist/ella-python/lib/python3.7/site-packages/sqlalchemy/orm/session.py", line 2313, in flush
[36mella_1        |[0m     self._flush(objects)
[36mella_1        |[0m   File "/dist/ella-python/lib/python3.7/site-packages/sqlalchemy/orm/session.py", line 2440, in _flush
[36mella_1        |[0m     transaction.rollback(_capture_exception=True)
[36mella_1        |[0m   File "/dist/ella-python/lib/python3.7/site-packages/sqlalchemy/util/langhelpers.py", line 66, in __exit__
[36mella_1        |[0m     compat.reraise(exc_type, exc_value, exc_tb)
[36mella_1        |[0m   File "/dist/ella-python/lib/python3.7/site-packages/sqlalchemy/util/compat.py", line 249, in reraise
[36mella_1        |[0m     raise value
[36mella_1        |[0m   File "/dist/ella-python/lib/python3.7/site-packages/sqlalchemy/orm/session.py", line 2404, in _flush
[36mella_1        |[0m     flush_context.execute()
[36mella_1        |[0m   File "/dist/ella-python/lib/python3.7/site-packages/sqlalchemy/orm/unitofwork.py", line 395, in execute
[36mella_1        |[0m     rec.execute(self)
[36mella_1        |[0m   File "/dist/ella-python/lib/python3.7/site-packages/sqlalchemy/orm/unitofwork.py", line 560, in execute
[36mella_1        |[0m     uow
[36mella_1        |[0m   File "/dist/ella-python/lib/python3.7/site-packages/sqlalchemy/orm/persistence.py", line 181, in save_obj
[36mella_1        |[0m     mapper, table, insert)
[36mella_1        |[0m   File "/dist/ella-python/lib/python3.7/site-packages/sqlalchemy/orm/persistence.py", line 872, in _emit_insert_statements
[36mella_1        |[0m     execute(statement, params)
[36mella_1        |[0m   File "/dist/ella-python/lib/python3.7/site-packages/sqlalchemy/engine/base.py", line 948, in execute
[36mella_1        |[0m     return meth(self, multiparams, params)
[36mella_1        |[0m   File "/dist/ella-python/lib/python3.7/site-packages/sqlalchemy/sql/elements.py", line 269, in _execute_on_connection
[36mella_1        |[0m     return connection._execute_clauseelement(self, multiparams, params)
[36mella_1        |[0m   File "/dist/ella-python/lib/python3.7/site-packages/sqlalchemy/engine/base.py", line 1060, in _execute_clauseelement
[36mella_1        |[0m     compiled_sql, distilled_params
[36mella_1        |[0m   File "/dist/ella-python/lib/python3.7/site-packages/sqlalchemy/engine/base.py", line 1200, in _execute_context
[36mella_1        |[0m     context)
[36mella_1        |[0m   File "/dist/ella-python/lib/python3.7/site-packages/sqlalchemy/engine/base.py", line 1409, in _handle_dbapi_exception
[36mella_1        |[0m     util.raise_from_cause(newraise, exc_info)
[36mella_1        |[0m   File "/dist/ella-python/lib/python3.7/site-packages/sqlalchemy/util/compat.py", line 265, in raise_from_cause
[36mella_1        |[0m     reraise(type(exception), exception, tb=exc_tb, cause=cause)
[36mella_1        |[0m   File "/dist/ella-python/lib/python3.7/site-packages/sqlalchemy/util/compat.py", line 248, in reraise
[36mella_1        |[0m     raise value.with_traceback(tb)
[36mella_1        |[0m   File "/dist/ella-python/lib/python3.7/site-packages/sqlalchemy/engine/base.py", line 1193, in _execute_context
[36mella_1        |[0m     context)
[36mella_1        |[0m   File "/dist/ella-python/lib/python3.7/site-packages/sqlalchemy/engine/default.py", line 509, in do_execute
[36mella_1        |[0m     cursor.execute(statement, parameters)
[36mella_1        |[0m psycopg2.ProgrammingError: relation "resourcelog" does not exist
[36mella_1        |[0m LINE 1: INSERT INTO resourcelog (remote_addr, time, duration, userse...
[36mella_1        |[0m                     ^
[36mella_1        |[0m 
[36mella_1        |[0m 2020-09-17 06:40:22,556 [INFO] werkzeug: 172.20.0.1 - - [17/Sep/2020 06:40:22] "GET /api/v1/config/ HTTP/1.1" 200 -
[36mella_1        |[0m 2020-09-17 06:40:22.685 UTC [233] ERROR:  relation "broadcast" does not exist at character 171
[36mella_1        |[0m 2020-09-17 06:40:22.685 UTC [233] STATEMENT:  SELECT broadcast.id AS broadcast_id, broadcast.date_created AS broadcast_date_created, broadcast.message AS broadcast_message, broadcast.active AS broadcast_active 
[36mella_1        |[0m 	FROM broadcast 
[36mella_1        |[0m 	WHERE broadcast.active IS true ORDER BY broadcast.date_created
[36mella_1        |[0m 2020-09-17 06:40:22,691 [ERROR] flask.app: Exception on /api/v1/broadcasts/ [GET]
[36mella_1        |[0m Traceback (most recent call last):
[36mella_1        |[0m   File "/dist/ella-python/lib/python3.7/site-packages/flask/app.py", line 1813, in full_dispatch_request
[36mella_1        |[0m     rv = self.dispatch_request()
[36mella_1        |[0m   File "/dist/ella-python/lib/python3.7/site-packages/flask/app.py", line 1799, in dispatch_request
[36mella_1        |[0m     return self.view_functions[rule.endpoint](**req.view_args)
[36mella_1        |[0m   File "/dist/ella-python/lib/python3.7/site-packages/flask_restful/__init__.py", line 458, in wrapper
[36mella_1        |[0m     resp = resource(*args, **kwargs)
[36mella_1        |[0m   File "/dist/ella-python/lib/python3.7/site-packages/flask/views.py", line 88, in view
[36mella_1        |[0m     return self.dispatch_request(*args, **kwargs)
[36mella_1        |[0m   File "/dist/ella-python/lib/python3.7/site-packages/flask_restful/__init__.py", line 573, in dispatch_request
[36mella_1        |[0m     resp = meth(*args, **kwargs)
[36mella_1        |[0m   File "/ella/src/api/util/util.py", line 229, in inner
[36mella_1        |[0m     return func(db.session, *args, **kwargs)
[36mella_1        |[0m   File "/ella/src/api/util/util.py", line 218, in inner
[36mella_1        |[0m     return func(*args, **kwargs)
[36mella_1        |[0m   File "/ella/src/api/util/util.py", line 435, in inner
[36mella_1        |[0m     return func(*args, **kwargs)
[36mella_1        |[0m   File "/ella/src/api/v1/resources/broadcast.py", line 56, in get
[36mella_1        |[0m     .order_by(broadcast.Broadcast.date_created)
[36mella_1        |[0m   File "/dist/ella-python/lib/python3.7/site-packages/sqlalchemy/orm/query.py", line 2843, in all
[36mella_1        |[0m     return list(self)
[36mella_1        |[0m   File "/dist/ella-python/lib/python3.7/site-packages/sqlalchemy/orm/query.py", line 2995, in __iter__
[36mella_1        |[0m     return self._execute_and_instances(context)
[36mella_1        |[0m   File "/dist/ella-python/lib/python3.7/site-packages/sqlalchemy/orm/query.py", line 3018, in _execute_and_instances
[36mella_1        |[0m     result = conn.execute(querycontext.statement, self._params)
[36mella_1        |[0m   File "/dist/ella-python/lib/python3.7/site-packages/sqlalchemy/engine/base.py", line 948, in execute
[36mella_1        |[0m     return meth(self, multiparams, params)
[36mella_1        |[0m   File "/dist/ella-python/lib/python3.7/site-packages/sqlalchemy/sql/elements.py", line 269, in _execute_on_connection
[36mella_1        |[0m     return connection._execute_clauseelement(self, multiparams, params)
[36mella_1        |[0m   File "/dist/ella-python/lib/python3.7/site-packages/sqlalchemy/engine/base.py", line 1060, in _execute_clauseelement
[36mella_1        |[0m     compiled_sql, distilled_params
[36mella_1        |[0m   File "/dist/ella-python/lib/python3.7/site-packages/sqlalchemy/engine/base.py", line 1200, in _execute_context
[36mella_1        |[0m     context)
[36mella_1        |[0m   File "/dist/ella-python/lib/python3.7/site-packages/sqlalchemy/engine/base.py", line 1409, in _handle_dbapi_exception
[36mella_1        |[0m     util.raise_from_cause(newraise, exc_info)
[36mella_1        |[0m   File "/dist/ella-python/lib/python3.7/site-packages/sqlalchemy/util/compat.py", line 265, in raise_from_cause
[36mella_1        |[0m     reraise(type(exception), exception, tb=exc_tb, cause=cause)
[36mella_1        |[0m   File "/dist/ella-python/lib/python3.7/site-packages/sqlalchemy/util/compat.py", line 248, in reraise
[36mella_1        |[0m     raise value.with_traceback(tb)
[36mella_1        |[0m   File "/dist/ella-python/lib/python3.7/site-packages/sqlalchemy/engine/base.py", line 1193, in _execute_context
[36mella_1        |[0m     context)
[36mella_1        |[0m   File "/dist/ella-python/lib/python3.7/site-packages/sqlalchemy/engine/default.py", line 509, in do_execute
[36mella_1        |[0m     cursor.execute(statement, parameters)
[36mella_1        |[0m psycopg2.ProgrammingError: relation "broadcast" does not exist
[36mella_1        |[0m LINE 2: FROM broadcast 
[36mella_1        |[0m              ^
[36mella_1        |[0m 
[36mella_1        |[0m 2020-09-17 06:40:22.723 UTC [233] ERROR:  relation "resourcelog" does not exist at character 13
[36mella_1        |[0m 2020-09-17 06:40:22.723 UTC [233] STATEMENT:  INSERT INTO resourcelog (remote_addr, time, duration, usersession_id, method, resource, query, response, response_size, payload, payload_size, statuscode) VALUES ('172.20.0.1', '2020-09-17T06:40:22.722643+00:00'::timestamptz, 26, NULL, 'GET', '/api/v1/broadcasts/', '', NULL, 36, NULL, 0, 500) RETURNING resourcelog.id
[36mella_1        |[0m 2020-09-17 06:40:22,727 [ERROR] flask.app: Something went wrong when commiting resourcelog entry
[36mella_1        |[0m Traceback (most recent call last):
[36mella_1        |[0m   File "/ella/src/api/main.py", line 47, in after_request
[36mella_1        |[0m     db.session.commit()
[36mella_1        |[0m   File "/dist/ella-python/lib/python3.7/site-packages/sqlalchemy/orm/scoping.py", line 153, in do
[36mella_1        |[0m     return getattr(self.registry(), name)(*args, **kwargs)
[36mella_1        |[0m   File "/dist/ella-python/lib/python3.7/site-packages/sqlalchemy/orm/session.py", line 954, in commit
[36mella_1        |[0m     self.transaction.commit()
[36mella_1        |[0m   File "/dist/ella-python/lib/python3.7/site-packages/sqlalchemy/orm/session.py", line 467, in commit
[36mella_1        |[0m     self._prepare_impl()
[36mella_1        |[0m   File "/dist/ella-python/lib/python3.7/site-packages/sqlalchemy/orm/session.py", line 447, in _prepare_impl
[36mella_1        |[0m     self.session.flush()
[36mella_1        |[0m   File "/dist/ella-python/lib/python3.7/site-packages/sqlalchemy/orm/session.py", line 2313, in flush
[36mella_1        |[0m     self._flush(objects)
[36mella_1        |[0m   File "/dist/ella-python/lib/python3.7/site-packages/sqlalchemy/orm/session.py", line 2440, in _flush
[36mella_1        |[0m     transaction.rollback(_capture_exception=True)
[36mella_1        |[0m   File "/dist/ella-python/lib/python3.7/site-packages/sqlalchemy/util/langhelpers.py", line 66, in __exit__
[36mella_1        |[0m     compat.reraise(exc_type, exc_value, exc_tb)
[36mella_1        |[0m   File "/dist/ella-python/lib/python3.7/site-packages/sqlalchemy/util/compat.py", line 249, in reraise
[36mella_1        |[0m     raise value
[36mella_1        |[0m   File "/dist/ella-python/lib/python3.7/site-packages/sqlalchemy/orm/session.py", line 2404, in _flush
[36mella_1        |[0m     flush_context.execute()
[36mella_1        |[0m   File "/dist/ella-python/lib/python3.7/site-packages/sqlalchemy/orm/unitofwork.py", line 395, in execute
[36mella_1        |[0m     rec.execute(self)
[36mella_1        |[0m   File "/dist/ella-python/lib/python3.7/site-packages/sqlalchemy/orm/unitofwork.py", line 560, in execute
[36mella_1        |[0m     uow
[36mella_1        |[0m   File "/dist/ella-python/lib/python3.7/site-packages/sqlalchemy/orm/persistence.py", line 181, in save_obj
[36mella_1        |[0m     mapper, table, insert)
[36mella_1        |[0m   File "/dist/ella-python/lib/python3.7/site-packages/sqlalchemy/orm/persistence.py", line 872, in _emit_insert_statements
[36mella_1        |[0m     execute(statement, params)
[36mella_1        |[0m   File "/dist/ella-python/lib/python3.7/site-packages/sqlalchemy/engine/base.py", line 948, in execute
[36mella_1        |[0m     return meth(self, multiparams, params)
[36mella_1        |[0m   File "/dist/ella-python/lib/python3.7/site-packages/sqlalchemy/sql/elements.py", line 269, in _execute_on_connection
[36mella_1        |[0m     return connection._execute_clauseelement(self, multiparams, params)
[36mella_1        |[0m   File "/dist/ella-python/lib/python3.7/site-packages/sqlalchemy/engine/base.py", line 1060, in _execute_clauseelement
[36mella_1        |[0m     compiled_sql, distilled_params
[36mella_1        |[0m   File "/dist/ella-python/lib/python3.7/site-packages/sqlalchemy/engine/base.py", line 1200, in _execute_context
[36mella_1        |[0m     context)
[36mella_1        |[0m   File "/dist/ella-python/lib/python3.7/site-packages/sqlalchemy/engine/base.py", line 1409, in _handle_dbapi_exception
[36mella_1        |[0m     util.raise_from_cause(newraise, exc_info)
[36mella_1        |[0m   File "/dist/ella-python/lib/python3.7/site-packages/sqlalchemy/util/compat.py", line 265, in raise_from_cause
[36mella_1        |[0m     reraise(type(exception), exception, tb=exc_tb, cause=cause)
[36mella_1        |[0m   File "/dist/ella-python/lib/python3.7/site-packages/sqlalchemy/util/compat.py", line 248, in reraise
[36mella_1        |[0m     raise value.with_traceback(tb)
[36mella_1        |[0m   File "/dist/ella-python/lib/python3.7/site-packages/sqlalchemy/engine/base.py", line 1193, in _execute_context
[36mella_1        |[0m     context)
[36mella_1        |[0m   File "/dist/ella-python/lib/python3.7/site-packages/sqlalchemy/engine/default.py", line 509, in do_execute
[36mella_1        |[0m     cursor.execute(statement, parameters)
[36mella_1        |[0m psycopg2.ProgrammingError: relation "resourcelog" does not exist
[36mella_1        |[0m LINE 1: INSERT INTO resourcelog (remote_addr, time, duration, userse...
[36mella_1        |[0m                     ^
[36mella_1        |[0m 
[36mella_1        |[0m 2020-09-17 06:40:22,731 [INFO] werkzeug: 172.20.0.1 - - [17/Sep/2020 06:40:22] "GET /api/v1/broadcasts/ HTTP/1.1" 500 -
[36mella_1        |[0m 2020-09-17 06:40:22,826 [INFO] werkzeug: 172.20.0.1 - - [17/Sep/2020 06:40:22] "GET /fonts/SourceSansPro-Regular.otf.woff2 HTTP/1.1" 200 -
[36mella_1        |[0m 2020-09-17 06:40:22,845 [INFO] werkzeug: 172.20.0.1 - - [17/Sep/2020 06:40:22] "GET /fonts/WorkSans-SemiBold.woff2 HTTP/1.1" 200 -
[36mella_1        |[0m 2020-09-17 06:40:22,877 [INFO] werkzeug: 172.20.0.1 - - [17/Sep/2020 06:40:22] "GET /fonts/SourceSansPro-Semibold.otf.woff2 HTTP/1.1" 200 -
[36mella_1        |[0m 2020-09-17 06:40:22,891 [INFO] werkzeug: 172.20.0.1 - - [17/Sep/2020 06:40:22] "GET /fonts/WorkSans-Medium.woff2 HTTP/1.1" 200 -
[36mella_1        |[0m 2020-09-17 06:40:23,228 [INFO] werkzeug: 172.20.0.1 - - [17/Sep/2020 06:40:23] "GET /favicon.ico HTTP/1.1" 404 -
[36mella_1        |[0m 2020-09-17 06:40:30,157 [INFO] werkzeug: 172.20.0.1 - - [17/Sep/2020 06:40:30] "GET /fonts/WorkSans-Bold.woff2 HTTP/1.1" 200 -
[36mella_1        |[0m 2020-09-17 06:40:48.363 UTC [233] ERROR:  relation "user" does not exist at character 397
[36mella_1        |[0m 2020-09-17 06:40:48.363 UTC [233] STATEMENT:  SELECT "user".id AS user_id, "user".username AS user_username, "user".first_name AS user_first_name, "user".last_name AS user_last_name, "user".email AS user_email, "user".group_id AS user_group_id, "user".password AS user_password, "user".password_expiry AS user_password_expiry, "user".active AS user_active, "user".incorrect_logins AS user_incorrect_logins, "user".config AS user_config 
[36mella_1        |[0m 	FROM "user" 
[36mella_1        |[0m 	WHERE "user".username = 'testuser1'
[36mella_1        |[0m 2020-09-17 06:40:48,366 [ERROR] flask.app: Exception on /api/v1/users/actions/changepassword/ [POST]
[36mella_1        |[0m Traceback (most recent call last):
[36mella_1        |[0m   File "/dist/ella-python/lib/python3.7/site-packages/flask/app.py", line 1813, in full_dispatch_request
[36mella_1        |[0m     rv = self.dispatch_request()
[36mella_1        |[0m   File "/dist/ella-python/lib/python3.7/site-packages/flask/app.py", line 1799, in dispatch_request
[36mella_1        |[0m     return self.view_functions[rule.endpoint](**req.view_args)
[36mella_1        |[0m   File "/dist/ella-python/lib/python3.7/site-packages/flask_restful/__init__.py", line 458, in wrapper
[36mella_1        |[0m     resp = resource(*args, **kwargs)
[36mella_1        |[0m   File "/dist/ella-python/lib/python3.7/site-packages/flask/views.py", line 88, in view
[36mella_1        |[0m     return self.dispatch_request(*args, **kwargs)
[36mella_1        |[0m   File "/dist/ella-python/lib/python3.7/site-packages/flask_restful/__init__.py", line 573, in dispatch_request
[36mella_1        |[0m     resp = meth(*args, **kwargs)
[36mella_1        |[0m   File "/ella/src/api/util/util.py", line 229, in inner
[36mella_1        |[0m     return func(db.session, *args, **kwargs)
[36mella_1        |[0m   File "/ella/src/api/util/util.py", line 218, in inner
[36mella_1        |[0m     return func(*args, **kwargs)
[36mella_1        |[0m   File "/ella/src/api/util/util.py", line 343, in inner
[36mella_1        |[0m     return func(*args, data=data, **kwargs)
[36mella_1        |[0m   File "/ella/src/api/v1/resources/user.py", line 110, in post
[36mella_1        |[0m     change_password(session, username, password, new_password)
[36mella_1        |[0m   File "/ella/src/api/util/useradmin.py", line 164, in change_password
[36mella_1        |[0m     user_object = get_user(session, user_or_username)
[36mella_1        |[0m   File "/ella/src/api/util/useradmin.py", line 30, in get_user
[36mella_1        |[0m     u = session.query(user.User).filter(user.User.username == user_or_username).one_or_none()
[36mella_1        |[0m   File "/dist/ella-python/lib/python3.7/site-packages/sqlalchemy/orm/query.py", line 2924, in one_or_none
[36mella_1        |[0m     ret = list(self)
[36mella_1        |[0m   File "/dist/ella-python/lib/python3.7/site-packages/sqlalchemy/orm/query.py", line 2995, in __iter__
[36mella_1        |[0m     return self._execute_and_instances(context)
[36mella_1        |[0m   File "/dist/ella-python/lib/python3.7/site-packages/sqlalchemy/orm/query.py", line 3018, in _execute_and_instances
[36mella_1        |[0m     result = conn.execute(querycontext.statement, self._params)
[36mella_1        |[0m   File "/dist/ella-python/lib/python3.7/site-packages/sqlalchemy/engine/base.py", line 948, in execute
[36mella_1        |[0m     return meth(self, multiparams, params)
[36mella_1        |[0m   File "/dist/ella-python/lib/python3.7/site-packages/sqlalchemy/sql/elements.py", line 269, in _execute_on_connection
[36mella_1        |[0m     return connection._execute_clauseelement(self, multiparams, params)
[36mella_1        |[0m   File "/dist/ella-python/lib/python3.7/site-packages/sqlalchemy/engine/base.py", line 1060, in _execute_clauseelement
[36mella_1        |[0m     compiled_sql, distilled_params
[36mella_1        |[0m   File "/dist/ella-python/lib/python3.7/site-packages/sqlalchemy/engine/base.py", line 1200, in _execute_context
[36mella_1        |[0m     context)
[36mella_1        |[0m   File "/dist/ella-python/lib/python3.7/site-packages/sqlalchemy/engine/base.py", line 1409, in _handle_dbapi_exception
[36mella_1        |[0m     util.raise_from_cause(newraise, exc_info)
[36mella_1        |[0m   File "/dist/ella-python/lib/python3.7/site-packages/sqlalchemy/util/compat.py", line 265, in raise_from_cause
[36mella_1        |[0m     reraise(type(exception), exception, tb=exc_tb, cause=cause)
[36mella_1        |[0m   File "/dist/ella-python/lib/python3.7/site-packages/sqlalchemy/util/compat.py", line 248, in reraise
[36mella_1        |[0m     raise value.with_traceback(tb)
[36mella_1        |[0m   File "/dist/ella-python/lib/python3.7/site-packages/sqlalchemy/engine/base.py", line 1193, in _execute_context
[36mella_1        |[0m     context)
[36mella_1        |[0m   File "/dist/ella-python/lib/python3.7/site-packages/sqlalchemy/engine/default.py", line 509, in do_execute
[36mella_1        |[0m     cursor.execute(statement, parameters)
[36mella_1        |[0m psycopg2.ProgrammingError: relation "user" does not exist
[36mella_1        |[0m LINE 2: FROM "user" 
[36mella_1        |[0m              ^
[36mella_1        |[0m 
[36mella_1        |[0m 2020-09-17 06:40:48,370 [WARNING] flask.app: None - POST - http://localhost:5000/api/v1/users/actions/changepassword/ - [PAYLOAD HIDDEN] - 36 - 35ms
[36mella_1        |[0m 2020-09-17 06:40:48.373 UTC [233] ERROR:  relation "resourcelog" does not exist at character 13
[36mella_1        |[0m 2020-09-17 06:40:48.373 UTC [233] STATEMENT:  INSERT INTO resourcelog (remote_addr, time, duration, usersession_id, method, resource, query, response, response_size, payload, payload_size, statuscode) VALUES ('172.20.0.1', '2020-09-17T06:40:48.372918+00:00'::timestamptz, 35, NULL, 'POST', '/api/v1/users/actions/changepassword/', '', NULL, 36, NULL, 0, 500) RETURNING resourcelog.id
[36mella_1        |[0m 2020-09-17 06:40:48,375 [ERROR] flask.app: Something went wrong when commiting resourcelog entry
[36mella_1        |[0m Traceback (most recent call last):
[36mella_1        |[0m   File "/ella/src/api/main.py", line 47, in after_request
[36mella_1        |[0m     db.session.commit()
[36mella_1        |[0m   File "/dist/ella-python/lib/python3.7/site-packages/sqlalchemy/orm/scoping.py", line 153, in do
[36mella_1        |[0m     return getattr(self.registry(), name)(*args, **kwargs)
[36mella_1        |[0m   File "/dist/ella-python/lib/python3.7/site-packages/sqlalchemy/orm/session.py", line 954, in commit
[36mella_1        |[0m     self.transaction.commit()
[36mella_1        |[0m   File "/dist/ella-python/lib/python3.7/site-packages/sqlalchemy/orm/session.py", line 467, in commit
[36mella_1        |[0m     self._prepare_impl()
[36mella_1        |[0m   File "/dist/ella-python/lib/python3.7/site-packages/sqlalchemy/orm/session.py", line 447, in _prepare_impl
[36mella_1        |[0m     self.session.flush()
[36mella_1        |[0m   File "/dist/ella-python/lib/python3.7/site-packages/sqlalchemy/orm/session.py", line 2313, in flush
[36mella_1        |[0m     self._flush(objects)
[36mella_1        |[0m   File "/dist/ella-python/lib/python3.7/site-packages/sqlalchemy/orm/session.py", line 2440, in _flush
[36mella_1        |[0m     transaction.rollback(_capture_exception=True)
[36mella_1        |[0m   File "/dist/ella-python/lib/python3.7/site-packages/sqlalchemy/util/langhelpers.py", line 66, in __exit__
[36mella_1        |[0m     compat.reraise(exc_type, exc_value, exc_tb)
[36mella_1        |[0m   File "/dist/ella-python/lib/python3.7/site-packages/sqlalchemy/util/compat.py", line 249, in reraise
[36mella_1        |[0m     raise value
[36mella_1        |[0m   File "/dist/ella-python/lib/python3.7/site-packages/sqlalchemy/orm/session.py", line 2404, in _flush
[36mella_1        |[0m     flush_context.execute()
[36mella_1        |[0m   File "/dist/ella-python/lib/python3.7/site-packages/sqlalchemy/orm/unitofwork.py", line 395, in execute
[36mella_1        |[0m     rec.execute(self)
[36mella_1        |[0m   File "/dist/ella-python/lib/python3.7/site-packages/sqlalchemy/orm/unitofwork.py", line 560, in execute
[36mella_1        |[0m     uow
[36mella_1        |[0m   File "/dist/ella-python/lib/python3.7/site-packages/sqlalchemy/orm/persistence.py", line 181, in save_obj
[36mella_1        |[0m     mapper, table, insert)
[36mella_1        |[0m   File "/dist/ella-python/lib/python3.7/site-packages/sqlalchemy/orm/persistence.py", line 872, in _emit_insert_statements
[36mella_1        |[0m     execute(statement, params)
[36mella_1        |[0m   File "/dist/ella-python/lib/python3.7/site-packages/sqlalchemy/engine/base.py", line 948, in execute
[36mella_1        |[0m     return meth(self, multiparams, params)
[36mella_1        |[0m   File "/dist/ella-python/lib/python3.7/site-packages/sqlalchemy/sql/elements.py", line 269, in _execute_on_connection
[36mella_1        |[0m     return connection._execute_clauseelement(self, multiparams, params)
[36mella_1        |[0m   File "/dist/ella-python/lib/python3.7/site-packages/sqlalchemy/engine/base.py", line 1060, in _execute_clauseelement
[36mella_1        |[0m     compiled_sql, distilled_params
[36mella_1        |[0m   File "/dist/ella-python/lib/python3.7/site-packages/sqlalchemy/engine/base.py", line 1200, in _execute_context
[36mella_1        |[0m     context)
[36mella_1        |[0m   File "/dist/ella-python/lib/python3.7/site-packages/sqlalchemy/engine/base.py", line 1409, in _handle_dbapi_exception
[36mella_1        |[0m     util.raise_from_cause(newraise, exc_info)
[36mella_1        |[0m   File "/dist/ella-python/lib/python3.7/site-packages/sqlalchemy/util/compat.py", line 265, in raise_from_cause
[36mella_1        |[0m     reraise(type(exception), exception, tb=exc_tb, cause=cause)
[36mella_1        |[0m   File "/dist/ella-python/lib/python3.7/site-packages/sqlalchemy/util/compat.py", line 248, in reraise
[36mella_1        |[0m     raise value.with_traceback(tb)
[36mella_1        |[0m   File "/dist/ella-python/lib/python3.7/site-packages/sqlalchemy/engine/base.py", line 1193, in _execute_context
[36mella_1        |[0m     context)
[36mella_1        |[0m   File "/dist/ella-python/lib/python3.7/site-packages/sqlalchemy/engine/default.py", line 509, in do_execute
[36mella_1        |[0m     cursor.execute(statement, parameters)
[36mella_1        |[0m psycopg2.ProgrammingError: relation "resourcelog" does not exist
[36mella_1        |[0m LINE 1: INSERT INTO resourcelog (remote_addr, time, duration, userse...
[36mella_1        |[0m                     ^
[36mella_1        |[0m 
[36mella_1        |[0m 2020-09-17 06:40:48,378 [INFO] werkzeug: 172.20.0.1 - - [17/Sep/2020 06:40:48] "POST /api/v1/users/actions/changepassword/ HTTP/1.1" 500 -
