2020-09-16 07:59:29,776 [INFO] __main__: Starting polling worker
2020-09-16 07:59:29,777 [INFO] __main__: Using annotation service at: http://ella-anno:6000
Traceback (most recent call last):
  File "src/api/polling.py", line 402, in polling
    loop(session)
  File "src/api/polling.py", line 363, in loop
    session.connection()
  File "/dist/ella-python/lib/python3.7/site-packages/sqlalchemy/orm/scoping.py", line 153, in do
    return getattr(self.registry(), name)(*args, **kwargs)
  File "/dist/ella-python/lib/python3.7/site-packages/sqlalchemy/orm/session.py", line 1046, in connection
    execution_options=execution_options)
  File "/dist/ella-python/lib/python3.7/site-packages/sqlalchemy/orm/session.py", line 1051, in _connection_for_bind
    engine, execution_options)
  File "/dist/ella-python/lib/python3.7/site-packages/sqlalchemy/orm/session.py", line 409, in _connection_for_bind
    conn = bind.contextual_connect()
  File "/dist/ella-python/lib/python3.7/site-packages/sqlalchemy/engine/base.py", line 2123, in contextual_connect
    self._wrap_pool_connect(self.pool.connect, None),
  File "/dist/ella-python/lib/python3.7/site-packages/sqlalchemy/engine/base.py", line 2162, in _wrap_pool_connect
    e, dialect, self)
  File "/dist/ella-python/lib/python3.7/site-packages/sqlalchemy/engine/base.py", line 1472, in _handle_dbapi_exception_noconnection
    util.raise_from_cause(newraise, exc_info)
  File "/dist/ella-python/lib/python3.7/site-packages/sqlalchemy/util/compat.py", line 265, in raise_from_cause
    reraise(type(exception), exception, tb=exc_tb, cause=cause)
  File "/dist/ella-python/lib/python3.7/site-packages/sqlalchemy/util/compat.py", line 248, in reraise
    raise value.with_traceback(tb)
  File "/dist/ella-python/lib/python3.7/site-packages/sqlalchemy/engine/base.py", line 2158, in _wrap_pool_connect
    return fn()
  File "/dist/ella-python/lib/python3.7/site-packages/sqlalchemy/pool.py", line 400, in connect
    return _ConnectionFairy._checkout(self)
  File "/dist/ella-python/lib/python3.7/site-packages/sqlalchemy/pool.py", line 788, in _checkout
    fairy = _ConnectionRecord.checkout(pool)
  File "/dist/ella-python/lib/python3.7/site-packages/sqlalchemy/pool.py", line 529, in checkout
    rec = pool._do_get()
  File "/dist/ella-python/lib/python3.7/site-packages/sqlalchemy/pool.py", line 1193, in _do_get
    self._dec_overflow()
  File "/dist/ella-python/lib/python3.7/site-packages/sqlalchemy/util/langhelpers.py", line 66, in __exit__
    compat.reraise(exc_type, exc_value, exc_tb)
  File "/dist/ella-python/lib/python3.7/site-packages/sqlalchemy/util/compat.py", line 249, in reraise
    raise value
  File "/dist/ella-python/lib/python3.7/site-packages/sqlalchemy/pool.py", line 1190, in _do_get
    return self._create_connection()
  File "/dist/ella-python/lib/python3.7/site-packages/sqlalchemy/pool.py", line 347, in _create_connection
    return _ConnectionRecord(self)
  File "/dist/ella-python/lib/python3.7/site-packages/sqlalchemy/pool.py", line 474, in __init__
    self.__connect(first_connect_check=True)
  File "/dist/ella-python/lib/python3.7/site-packages/sqlalchemy/pool.py", line 671, in __connect
    connection = pool._invoke_creator(self)
  File "/dist/ella-python/lib/python3.7/site-packages/sqlalchemy/engine/strategies.py", line 106, in connect
    return dialect.connect(*cargs, **cparams)
  File "/dist/ella-python/lib/python3.7/site-packages/sqlalchemy/engine/default.py", line 412, in connect
    return self.dbapi.connect(*cargs, **cparams)
  File "/dist/ella-python/lib/python3.7/site-packages/psycopg2/__init__.py", line 130, in connect
    conn = _connect(dsn, connection_factory=connection_factory, **kwasync)
psycopg2.OperationalError: could not connect to server: No such file or directory
	Is the server running locally and accepting
	connections on Unix domain socket "/socket/.s.PGSQL.5432"?

Traceback (most recent call last):
  File "src/api/polling.py", line 422, in <module>
    polling(db.session)
  File "src/api/polling.py", line 406, in polling
    raise e
  File "src/api/polling.py", line 402, in polling
    loop(session)
  File "src/api/polling.py", line 363, in loop
    session.connection()
  File "/dist/ella-python/lib/python3.7/site-packages/sqlalchemy/orm/scoping.py", line 153, in do
    return getattr(self.registry(), name)(*args, **kwargs)
  File "/dist/ella-python/lib/python3.7/site-packages/sqlalchemy/orm/session.py", line 1046, in connection
    execution_options=execution_options)
  File "/dist/ella-python/lib/python3.7/site-packages/sqlalchemy/orm/session.py", line 1051, in _connection_for_bind
    engine, execution_options)
  File "/dist/ella-python/lib/python3.7/site-packages/sqlalchemy/orm/session.py", line 409, in _connection_for_bind
    conn = bind.contextual_connect()
  File "/dist/ella-python/lib/python3.7/site-packages/sqlalchemy/engine/base.py", line 2123, in contextual_connect
    self._wrap_pool_connect(self.pool.connect, None),
  File "/dist/ella-python/lib/python3.7/site-packages/sqlalchemy/engine/base.py", line 2162, in _wrap_pool_connect
    e, dialect, self)
  File "/dist/ella-python/lib/python3.7/site-packages/sqlalchemy/engine/base.py", line 1472, in _handle_dbapi_exception_noconnection
    util.raise_from_cause(newraise, exc_info)
  File "/dist/ella-python/lib/python3.7/site-packages/sqlalchemy/util/compat.py", line 265, in raise_from_cause
    reraise(type(exception), exception, tb=exc_tb, cause=cause)
  File "/dist/ella-python/lib/python3.7/site-packages/sqlalchemy/util/compat.py", line 248, in reraise
    raise value.with_traceback(tb)
  File "/dist/ella-python/lib/python3.7/site-packages/sqlalchemy/engine/base.py", line 2158, in _wrap_pool_connect
    return fn()
  File "/dist/ella-python/lib/python3.7/site-packages/sqlalchemy/pool.py", line 400, in connect
    return _ConnectionFairy._checkout(self)
  File "/dist/ella-python/lib/python3.7/site-packages/sqlalchemy/pool.py", line 788, in _checkout
    fairy = _ConnectionRecord.checkout(pool)
  File "/dist/ella-python/lib/python3.7/site-packages/sqlalchemy/pool.py", line 529, in checkout
    rec = pool._do_get()
  File "/dist/ella-python/lib/python3.7/site-packages/sqlalchemy/pool.py", line 1193, in _do_get
    self._dec_overflow()
  File "/dist/ella-python/lib/python3.7/site-packages/sqlalchemy/util/langhelpers.py", line 66, in __exit__
    compat.reraise(exc_type, exc_value, exc_tb)
  File "/dist/ella-python/lib/python3.7/site-packages/sqlalchemy/util/compat.py", line 249, in reraise
    raise value
  File "/dist/ella-python/lib/python3.7/site-packages/sqlalchemy/pool.py", line 1190, in _do_get
    return self._create_connection()
  File "/dist/ella-python/lib/python3.7/site-packages/sqlalchemy/pool.py", line 347, in _create_connection
    return _ConnectionRecord(self)
  File "/dist/ella-python/lib/python3.7/site-packages/sqlalchemy/pool.py", line 474, in __init__
    self.__connect(first_connect_check=True)
  File "/dist/ella-python/lib/python3.7/site-packages/sqlalchemy/pool.py", line 671, in __connect
    connection = pool._invoke_creator(self)
  File "/dist/ella-python/lib/python3.7/site-packages/sqlalchemy/engine/strategies.py", line 106, in connect
    return dialect.connect(*cargs, **cparams)
  File "/dist/ella-python/lib/python3.7/site-packages/sqlalchemy/engine/default.py", line 412, in connect
    return self.dbapi.connect(*cargs, **cparams)
  File "/dist/ella-python/lib/python3.7/site-packages/psycopg2/__init__.py", line 130, in connect
    conn = _connect(dsn, connection_factory=connection_factory, **kwasync)
psycopg2.OperationalError: could not connect to server: No such file or directory
	Is the server running locally and accepting
	connections on Unix domain socket "/socket/.s.PGSQL.5432"?

2020-09-16 07:59:34,499 [INFO] __main__: Starting polling worker
2020-09-16 07:59:34,499 [INFO] __main__: Using annotation service at: http://ella-anno:6000
Traceback (most recent call last):
  File "src/api/polling.py", line 402, in polling
    loop(session)
  File "src/api/polling.py", line 363, in loop
    session.connection()
  File "/dist/ella-python/lib/python3.7/site-packages/sqlalchemy/orm/scoping.py", line 153, in do
    return getattr(self.registry(), name)(*args, **kwargs)
  File "/dist/ella-python/lib/python3.7/site-packages/sqlalchemy/orm/session.py", line 1046, in connection
    execution_options=execution_options)
  File "/dist/ella-python/lib/python3.7/site-packages/sqlalchemy/orm/session.py", line 1051, in _connection_for_bind
    engine, execution_options)
  File "/dist/ella-python/lib/python3.7/site-packages/sqlalchemy/orm/session.py", line 409, in _connection_for_bind
    conn = bind.contextual_connect()
  File "/dist/ella-python/lib/python3.7/site-packages/sqlalchemy/engine/base.py", line 2123, in contextual_connect
    self._wrap_pool_connect(self.pool.connect, None),
  File "/dist/ella-python/lib/python3.7/site-packages/sqlalchemy/engine/base.py", line 2162, in _wrap_pool_connect
    e, dialect, self)
  File "/dist/ella-python/lib/python3.7/site-packages/sqlalchemy/engine/base.py", line 1472, in _handle_dbapi_exception_noconnection
    util.raise_from_cause(newraise, exc_info)
  File "/dist/ella-python/lib/python3.7/site-packages/sqlalchemy/util/compat.py", line 265, in raise_from_cause
    reraise(type(exception), exception, tb=exc_tb, cause=cause)
  File "/dist/ella-python/lib/python3.7/site-packages/sqlalchemy/util/compat.py", line 248, in reraise
    raise value.with_traceback(tb)
  File "/dist/ella-python/lib/python3.7/site-packages/sqlalchemy/engine/base.py", line 2158, in _wrap_pool_connect
    return fn()
  File "/dist/ella-python/lib/python3.7/site-packages/sqlalchemy/pool.py", line 400, in connect
    return _ConnectionFairy._checkout(self)
  File "/dist/ella-python/lib/python3.7/site-packages/sqlalchemy/pool.py", line 788, in _checkout
    fairy = _ConnectionRecord.checkout(pool)
  File "/dist/ella-python/lib/python3.7/site-packages/sqlalchemy/pool.py", line 529, in checkout
    rec = pool._do_get()
  File "/dist/ella-python/lib/python3.7/site-packages/sqlalchemy/pool.py", line 1193, in _do_get
    self._dec_overflow()
  File "/dist/ella-python/lib/python3.7/site-packages/sqlalchemy/util/langhelpers.py", line 66, in __exit__
    compat.reraise(exc_type, exc_value, exc_tb)
  File "/dist/ella-python/lib/python3.7/site-packages/sqlalchemy/util/compat.py", line 249, in reraise
    raise value
  File "/dist/ella-python/lib/python3.7/site-packages/sqlalchemy/pool.py", line 1190, in _do_get
    return self._create_connection()
  File "/dist/ella-python/lib/python3.7/site-packages/sqlalchemy/pool.py", line 347, in _create_connection
    return _ConnectionRecord(self)
  File "/dist/ella-python/lib/python3.7/site-packages/sqlalchemy/pool.py", line 474, in __init__
    self.__connect(first_connect_check=True)
  File "/dist/ella-python/lib/python3.7/site-packages/sqlalchemy/pool.py", line 671, in __connect
    connection = pool._invoke_creator(self)
  File "/dist/ella-python/lib/python3.7/site-packages/sqlalchemy/engine/strategies.py", line 106, in connect
    return dialect.connect(*cargs, **cparams)
  File "/dist/ella-python/lib/python3.7/site-packages/sqlalchemy/engine/default.py", line 412, in connect
    return self.dbapi.connect(*cargs, **cparams)
  File "/dist/ella-python/lib/python3.7/site-packages/psycopg2/__init__.py", line 130, in connect
    conn = _connect(dsn, connection_factory=connection_factory, **kwasync)
psycopg2.OperationalError: could not connect to server: No such file or directory
	Is the server running locally and accepting
	connections on Unix domain socket "/socket/.s.PGSQL.5432"?

Traceback (most recent call last):
  File "src/api/polling.py", line 422, in <module>
    polling(db.session)
  File "src/api/polling.py", line 406, in polling
    raise e
  File "src/api/polling.py", line 402, in polling
    loop(session)
  File "src/api/polling.py", line 363, in loop
    session.connection()
  File "/dist/ella-python/lib/python3.7/site-packages/sqlalchemy/orm/scoping.py", line 153, in do
    return getattr(self.registry(), name)(*args, **kwargs)
  File "/dist/ella-python/lib/python3.7/site-packages/sqlalchemy/orm/session.py", line 1046, in connection
    execution_options=execution_options)
  File "/dist/ella-python/lib/python3.7/site-packages/sqlalchemy/orm/session.py", line 1051, in _connection_for_bind
    engine, execution_options)
  File "/dist/ella-python/lib/python3.7/site-packages/sqlalchemy/orm/session.py", line 409, in _connection_for_bind
    conn = bind.contextual_connect()
  File "/dist/ella-python/lib/python3.7/site-packages/sqlalchemy/engine/base.py", line 2123, in contextual_connect
    self._wrap_pool_connect(self.pool.connect, None),
  File "/dist/ella-python/lib/python3.7/site-packages/sqlalchemy/engine/base.py", line 2162, in _wrap_pool_connect
    e, dialect, self)
  File "/dist/ella-python/lib/python3.7/site-packages/sqlalchemy/engine/base.py", line 1472, in _handle_dbapi_exception_noconnection
    util.raise_from_cause(newraise, exc_info)
  File "/dist/ella-python/lib/python3.7/site-packages/sqlalchemy/util/compat.py", line 265, in raise_from_cause
    reraise(type(exception), exception, tb=exc_tb, cause=cause)
  File "/dist/ella-python/lib/python3.7/site-packages/sqlalchemy/util/compat.py", line 248, in reraise
    raise value.with_traceback(tb)
  File "/dist/ella-python/lib/python3.7/site-packages/sqlalchemy/engine/base.py", line 2158, in _wrap_pool_connect
    return fn()
  File "/dist/ella-python/lib/python3.7/site-packages/sqlalchemy/pool.py", line 400, in connect
    return _ConnectionFairy._checkout(self)
  File "/dist/ella-python/lib/python3.7/site-packages/sqlalchemy/pool.py", line 788, in _checkout
    fairy = _ConnectionRecord.checkout(pool)
  File "/dist/ella-python/lib/python3.7/site-packages/sqlalchemy/pool.py", line 529, in checkout
    rec = pool._do_get()
  File "/dist/ella-python/lib/python3.7/site-packages/sqlalchemy/pool.py", line 1193, in _do_get
    self._dec_overflow()
  File "/dist/ella-python/lib/python3.7/site-packages/sqlalchemy/util/langhelpers.py", line 66, in __exit__
    compat.reraise(exc_type, exc_value, exc_tb)
  File "/dist/ella-python/lib/python3.7/site-packages/sqlalchemy/util/compat.py", line 249, in reraise
    raise value
  File "/dist/ella-python/lib/python3.7/site-packages/sqlalchemy/pool.py", line 1190, in _do_get
    return self._create_connection()
  File "/dist/ella-python/lib/python3.7/site-packages/sqlalchemy/pool.py", line 347, in _create_connection
    return _ConnectionRecord(self)
  File "/dist/ella-python/lib/python3.7/site-packages/sqlalchemy/pool.py", line 474, in __init__
    self.__connect(first_connect_check=True)
  File "/dist/ella-python/lib/python3.7/site-packages/sqlalchemy/pool.py", line 671, in __connect
    connection = pool._invoke_creator(self)
  File "/dist/ella-python/lib/python3.7/site-packages/sqlalchemy/engine/strategies.py", line 106, in connect
    return dialect.connect(*cargs, **cparams)
  File "/dist/ella-python/lib/python3.7/site-packages/sqlalchemy/engine/default.py", line 412, in connect
    return self.dbapi.connect(*cargs, **cparams)
  File "/dist/ella-python/lib/python3.7/site-packages/psycopg2/__init__.py", line 130, in connect
    conn = _connect(dsn, connection_factory=connection_factory, **kwasync)
psycopg2.OperationalError: could not connect to server: No such file or directory
	Is the server running locally and accepting
	connections on Unix domain socket "/socket/.s.PGSQL.5432"?

2020-09-16 07:59:36,876 [INFO] __main__: Starting polling worker
2020-09-16 07:59:36,876 [INFO] __main__: Using annotation service at: http://ella-anno:6000
2020-09-16 08:07:26,570 [INFO] __main__: Starting polling worker
2020-09-16 08:07:26,570 [INFO] __main__: Using annotation service at: http://ella-anno:6000
Traceback (most recent call last):
  File "src/api/polling.py", line 402, in polling
    loop(session)
  File "src/api/polling.py", line 363, in loop
    session.connection()
  File "/dist/ella-python/lib/python3.7/site-packages/sqlalchemy/orm/scoping.py", line 153, in do
    return getattr(self.registry(), name)(*args, **kwargs)
  File "/dist/ella-python/lib/python3.7/site-packages/sqlalchemy/orm/session.py", line 1046, in connection
    execution_options=execution_options)
  File "/dist/ella-python/lib/python3.7/site-packages/sqlalchemy/orm/session.py", line 1051, in _connection_for_bind
    engine, execution_options)
  File "/dist/ella-python/lib/python3.7/site-packages/sqlalchemy/orm/session.py", line 409, in _connection_for_bind
    conn = bind.contextual_connect()
  File "/dist/ella-python/lib/python3.7/site-packages/sqlalchemy/engine/base.py", line 2123, in contextual_connect
    self._wrap_pool_connect(self.pool.connect, None),
  File "/dist/ella-python/lib/python3.7/site-packages/sqlalchemy/engine/base.py", line 2162, in _wrap_pool_connect
    e, dialect, self)
  File "/dist/ella-python/lib/python3.7/site-packages/sqlalchemy/engine/base.py", line 1472, in _handle_dbapi_exception_noconnection
    util.raise_from_cause(newraise, exc_info)
  File "/dist/ella-python/lib/python3.7/site-packages/sqlalchemy/util/compat.py", line 265, in raise_from_cause
    reraise(type(exception), exception, tb=exc_tb, cause=cause)
  File "/dist/ella-python/lib/python3.7/site-packages/sqlalchemy/util/compat.py", line 248, in reraise
    raise value.with_traceback(tb)
  File "/dist/ella-python/lib/python3.7/site-packages/sqlalchemy/engine/base.py", line 2158, in _wrap_pool_connect
    return fn()
  File "/dist/ella-python/lib/python3.7/site-packages/sqlalchemy/pool.py", line 400, in connect
    return _ConnectionFairy._checkout(self)
  File "/dist/ella-python/lib/python3.7/site-packages/sqlalchemy/pool.py", line 788, in _checkout
    fairy = _ConnectionRecord.checkout(pool)
  File "/dist/ella-python/lib/python3.7/site-packages/sqlalchemy/pool.py", line 529, in checkout
    rec = pool._do_get()
  File "/dist/ella-python/lib/python3.7/site-packages/sqlalchemy/pool.py", line 1193, in _do_get
    self._dec_overflow()
  File "/dist/ella-python/lib/python3.7/site-packages/sqlalchemy/util/langhelpers.py", line 66, in __exit__
    compat.reraise(exc_type, exc_value, exc_tb)
  File "/dist/ella-python/lib/python3.7/site-packages/sqlalchemy/util/compat.py", line 249, in reraise
    raise value
  File "/dist/ella-python/lib/python3.7/site-packages/sqlalchemy/pool.py", line 1190, in _do_get
    return self._create_connection()
  File "/dist/ella-python/lib/python3.7/site-packages/sqlalchemy/pool.py", line 347, in _create_connection
    return _ConnectionRecord(self)
  File "/dist/ella-python/lib/python3.7/site-packages/sqlalchemy/pool.py", line 474, in __init__
    self.__connect(first_connect_check=True)
  File "/dist/ella-python/lib/python3.7/site-packages/sqlalchemy/pool.py", line 671, in __connect
    connection = pool._invoke_creator(self)
  File "/dist/ella-python/lib/python3.7/site-packages/sqlalchemy/engine/strategies.py", line 106, in connect
    return dialect.connect(*cargs, **cparams)
  File "/dist/ella-python/lib/python3.7/site-packages/sqlalchemy/engine/default.py", line 412, in connect
    return self.dbapi.connect(*cargs, **cparams)
  File "/dist/ella-python/lib/python3.7/site-packages/psycopg2/__init__.py", line 130, in connect
    conn = _connect(dsn, connection_factory=connection_factory, **kwasync)
psycopg2.OperationalError: could not connect to server: No such file or directory
	Is the server running locally and accepting
	connections on Unix domain socket "/socket/.s.PGSQL.5432"?

Traceback (most recent call last):
  File "src/api/polling.py", line 422, in <module>
    polling(db.session)
  File "src/api/polling.py", line 406, in polling
    raise e
  File "src/api/polling.py", line 402, in polling
    loop(session)
  File "src/api/polling.py", line 363, in loop
    session.connection()
  File "/dist/ella-python/lib/python3.7/site-packages/sqlalchemy/orm/scoping.py", line 153, in do
    return getattr(self.registry(), name)(*args, **kwargs)
  File "/dist/ella-python/lib/python3.7/site-packages/sqlalchemy/orm/session.py", line 1046, in connection
    execution_options=execution_options)
  File "/dist/ella-python/lib/python3.7/site-packages/sqlalchemy/orm/session.py", line 1051, in _connection_for_bind
    engine, execution_options)
  File "/dist/ella-python/lib/python3.7/site-packages/sqlalchemy/orm/session.py", line 409, in _connection_for_bind
    conn = bind.contextual_connect()
  File "/dist/ella-python/lib/python3.7/site-packages/sqlalchemy/engine/base.py", line 2123, in contextual_connect
    self._wrap_pool_connect(self.pool.connect, None),
  File "/dist/ella-python/lib/python3.7/site-packages/sqlalchemy/engine/base.py", line 2162, in _wrap_pool_connect
    e, dialect, self)
  File "/dist/ella-python/lib/python3.7/site-packages/sqlalchemy/engine/base.py", line 1472, in _handle_dbapi_exception_noconnection
    util.raise_from_cause(newraise, exc_info)
  File "/dist/ella-python/lib/python3.7/site-packages/sqlalchemy/util/compat.py", line 265, in raise_from_cause
    reraise(type(exception), exception, tb=exc_tb, cause=cause)
  File "/dist/ella-python/lib/python3.7/site-packages/sqlalchemy/util/compat.py", line 248, in reraise
    raise value.with_traceback(tb)
  File "/dist/ella-python/lib/python3.7/site-packages/sqlalchemy/engine/base.py", line 2158, in _wrap_pool_connect
    return fn()
  File "/dist/ella-python/lib/python3.7/site-packages/sqlalchemy/pool.py", line 400, in connect
    return _ConnectionFairy._checkout(self)
  File "/dist/ella-python/lib/python3.7/site-packages/sqlalchemy/pool.py", line 788, in _checkout
    fairy = _ConnectionRecord.checkout(pool)
  File "/dist/ella-python/lib/python3.7/site-packages/sqlalchemy/pool.py", line 529, in checkout
    rec = pool._do_get()
  File "/dist/ella-python/lib/python3.7/site-packages/sqlalchemy/pool.py", line 1193, in _do_get
    self._dec_overflow()
  File "/dist/ella-python/lib/python3.7/site-packages/sqlalchemy/util/langhelpers.py", line 66, in __exit__
    compat.reraise(exc_type, exc_value, exc_tb)
  File "/dist/ella-python/lib/python3.7/site-packages/sqlalchemy/util/compat.py", line 249, in reraise
    raise value
  File "/dist/ella-python/lib/python3.7/site-packages/sqlalchemy/pool.py", line 1190, in _do_get
    return self._create_connection()
  File "/dist/ella-python/lib/python3.7/site-packages/sqlalchemy/pool.py", line 347, in _create_connection
    return _ConnectionRecord(self)
  File "/dist/ella-python/lib/python3.7/site-packages/sqlalchemy/pool.py", line 474, in __init__
    self.__connect(first_connect_check=True)
  File "/dist/ella-python/lib/python3.7/site-packages/sqlalchemy/pool.py", line 671, in __connect
    connection = pool._invoke_creator(self)
  File "/dist/ella-python/lib/python3.7/site-packages/sqlalchemy/engine/strategies.py", line 106, in connect
    return dialect.connect(*cargs, **cparams)
  File "/dist/ella-python/lib/python3.7/site-packages/sqlalchemy/engine/default.py", line 412, in connect
    return self.dbapi.connect(*cargs, **cparams)
  File "/dist/ella-python/lib/python3.7/site-packages/psycopg2/__init__.py", line 130, in connect
    conn = _connect(dsn, connection_factory=connection_factory, **kwasync)
psycopg2.OperationalError: could not connect to server: No such file or directory
	Is the server running locally and accepting
	connections on Unix domain socket "/socket/.s.PGSQL.5432"?

2020-09-16 08:07:28,585 [INFO] __main__: Starting polling worker
2020-09-16 08:07:28,586 [INFO] __main__: Using annotation service at: http://ella-anno:6000
Traceback (most recent call last):
  File "src/api/polling.py", line 402, in polling
    loop(session)
  File "src/api/polling.py", line 363, in loop
    session.connection()
  File "/dist/ella-python/lib/python3.7/site-packages/sqlalchemy/orm/scoping.py", line 153, in do
    return getattr(self.registry(), name)(*args, **kwargs)
  File "/dist/ella-python/lib/python3.7/site-packages/sqlalchemy/orm/session.py", line 1046, in connection
    execution_options=execution_options)
  File "/dist/ella-python/lib/python3.7/site-packages/sqlalchemy/orm/session.py", line 1051, in _connection_for_bind
    engine, execution_options)
  File "/dist/ella-python/lib/python3.7/site-packages/sqlalchemy/orm/session.py", line 409, in _connection_for_bind
    conn = bind.contextual_connect()
  File "/dist/ella-python/lib/python3.7/site-packages/sqlalchemy/engine/base.py", line 2123, in contextual_connect
    self._wrap_pool_connect(self.pool.connect, None),
  File "/dist/ella-python/lib/python3.7/site-packages/sqlalchemy/engine/base.py", line 2162, in _wrap_pool_connect
    e, dialect, self)
  File "/dist/ella-python/lib/python3.7/site-packages/sqlalchemy/engine/base.py", line 1472, in _handle_dbapi_exception_noconnection
    util.raise_from_cause(newraise, exc_info)
  File "/dist/ella-python/lib/python3.7/site-packages/sqlalchemy/util/compat.py", line 265, in raise_from_cause
    reraise(type(exception), exception, tb=exc_tb, cause=cause)
  File "/dist/ella-python/lib/python3.7/site-packages/sqlalchemy/util/compat.py", line 248, in reraise
    raise value.with_traceback(tb)
  File "/dist/ella-python/lib/python3.7/site-packages/sqlalchemy/engine/base.py", line 2158, in _wrap_pool_connect
    return fn()
  File "/dist/ella-python/lib/python3.7/site-packages/sqlalchemy/pool.py", line 400, in connect
    return _ConnectionFairy._checkout(self)
  File "/dist/ella-python/lib/python3.7/site-packages/sqlalchemy/pool.py", line 788, in _checkout
    fairy = _ConnectionRecord.checkout(pool)
  File "/dist/ella-python/lib/python3.7/site-packages/sqlalchemy/pool.py", line 529, in checkout
    rec = pool._do_get()
  File "/dist/ella-python/lib/python3.7/site-packages/sqlalchemy/pool.py", line 1193, in _do_get
    self._dec_overflow()
  File "/dist/ella-python/lib/python3.7/site-packages/sqlalchemy/util/langhelpers.py", line 66, in __exit__
    compat.reraise(exc_type, exc_value, exc_tb)
  File "/dist/ella-python/lib/python3.7/site-packages/sqlalchemy/util/compat.py", line 249, in reraise
    raise value
  File "/dist/ella-python/lib/python3.7/site-packages/sqlalchemy/pool.py", line 1190, in _do_get
    return self._create_connection()
  File "/dist/ella-python/lib/python3.7/site-packages/sqlalchemy/pool.py", line 347, in _create_connection
    return _ConnectionRecord(self)
  File "/dist/ella-python/lib/python3.7/site-packages/sqlalchemy/pool.py", line 474, in __init__
    self.__connect(first_connect_check=True)
  File "/dist/ella-python/lib/python3.7/site-packages/sqlalchemy/pool.py", line 671, in __connect
    connection = pool._invoke_creator(self)
  File "/dist/ella-python/lib/python3.7/site-packages/sqlalchemy/engine/strategies.py", line 106, in connect
    return dialect.connect(*cargs, **cparams)
  File "/dist/ella-python/lib/python3.7/site-packages/sqlalchemy/engine/default.py", line 412, in connect
    return self.dbapi.connect(*cargs, **cparams)
  File "/dist/ella-python/lib/python3.7/site-packages/psycopg2/__init__.py", line 130, in connect
    conn = _connect(dsn, connection_factory=connection_factory, **kwasync)
psycopg2.OperationalError: could not connect to server: No such file or directory
	Is the server running locally and accepting
	connections on Unix domain socket "/socket/.s.PGSQL.5432"?

Traceback (most recent call last):
  File "src/api/polling.py", line 422, in <module>
    polling(db.session)
  File "src/api/polling.py", line 406, in polling
    raise e
  File "src/api/polling.py", line 402, in polling
    loop(session)
  File "src/api/polling.py", line 363, in loop
    session.connection()
  File "/dist/ella-python/lib/python3.7/site-packages/sqlalchemy/orm/scoping.py", line 153, in do
    return getattr(self.registry(), name)(*args, **kwargs)
  File "/dist/ella-python/lib/python3.7/site-packages/sqlalchemy/orm/session.py", line 1046, in connection
    execution_options=execution_options)
  File "/dist/ella-python/lib/python3.7/site-packages/sqlalchemy/orm/session.py", line 1051, in _connection_for_bind
    engine, execution_options)
  File "/dist/ella-python/lib/python3.7/site-packages/sqlalchemy/orm/session.py", line 409, in _connection_for_bind
    conn = bind.contextual_connect()
  File "/dist/ella-python/lib/python3.7/site-packages/sqlalchemy/engine/base.py", line 2123, in contextual_connect
    self._wrap_pool_connect(self.pool.connect, None),
  File "/dist/ella-python/lib/python3.7/site-packages/sqlalchemy/engine/base.py", line 2162, in _wrap_pool_connect
    e, dialect, self)
  File "/dist/ella-python/lib/python3.7/site-packages/sqlalchemy/engine/base.py", line 1472, in _handle_dbapi_exception_noconnection
    util.raise_from_cause(newraise, exc_info)
  File "/dist/ella-python/lib/python3.7/site-packages/sqlalchemy/util/compat.py", line 265, in raise_from_cause
    reraise(type(exception), exception, tb=exc_tb, cause=cause)
  File "/dist/ella-python/lib/python3.7/site-packages/sqlalchemy/util/compat.py", line 248, in reraise
    raise value.with_traceback(tb)
  File "/dist/ella-python/lib/python3.7/site-packages/sqlalchemy/engine/base.py", line 2158, in _wrap_pool_connect
    return fn()
  File "/dist/ella-python/lib/python3.7/site-packages/sqlalchemy/pool.py", line 400, in connect
    return _ConnectionFairy._checkout(self)
  File "/dist/ella-python/lib/python3.7/site-packages/sqlalchemy/pool.py", line 788, in _checkout
    fairy = _ConnectionRecord.checkout(pool)
  File "/dist/ella-python/lib/python3.7/site-packages/sqlalchemy/pool.py", line 529, in checkout
    rec = pool._do_get()
  File "/dist/ella-python/lib/python3.7/site-packages/sqlalchemy/pool.py", line 1193, in _do_get
    self._dec_overflow()
  File "/dist/ella-python/lib/python3.7/site-packages/sqlalchemy/util/langhelpers.py", line 66, in __exit__
    compat.reraise(exc_type, exc_value, exc_tb)
  File "/dist/ella-python/lib/python3.7/site-packages/sqlalchemy/util/compat.py", line 249, in reraise
    raise value
  File "/dist/ella-python/lib/python3.7/site-packages/sqlalchemy/pool.py", line 1190, in _do_get
    return self._create_connection()
  File "/dist/ella-python/lib/python3.7/site-packages/sqlalchemy/pool.py", line 347, in _create_connection
    return _ConnectionRecord(self)
  File "/dist/ella-python/lib/python3.7/site-packages/sqlalchemy/pool.py", line 474, in __init__
    self.__connect(first_connect_check=True)
  File "/dist/ella-python/lib/python3.7/site-packages/sqlalchemy/pool.py", line 671, in __connect
    connection = pool._invoke_creator(self)
  File "/dist/ella-python/lib/python3.7/site-packages/sqlalchemy/engine/strategies.py", line 106, in connect
    return dialect.connect(*cargs, **cparams)
  File "/dist/ella-python/lib/python3.7/site-packages/sqlalchemy/engine/default.py", line 412, in connect
    return self.dbapi.connect(*cargs, **cparams)
  File "/dist/ella-python/lib/python3.7/site-packages/psycopg2/__init__.py", line 130, in connect
    conn = _connect(dsn, connection_factory=connection_factory, **kwasync)
psycopg2.OperationalError: could not connect to server: No such file or directory
	Is the server running locally and accepting
	connections on Unix domain socket "/socket/.s.PGSQL.5432"?

2020-09-16 08:07:30,623 [INFO] __main__: Starting polling worker
2020-09-16 08:07:30,624 [INFO] __main__: Using annotation service at: http://ella-anno:6000
2020-09-16 08:15:03,630 [INFO] __main__: Starting polling worker
2020-09-16 08:15:03,631 [INFO] __main__: Using annotation service at: http://ella-anno:6000
Traceback (most recent call last):
  File "src/api/polling.py", line 402, in polling
    loop(session)
  File "src/api/polling.py", line 363, in loop
    session.connection()
  File "/dist/ella-python/lib/python3.7/site-packages/sqlalchemy/orm/scoping.py", line 153, in do
    return getattr(self.registry(), name)(*args, **kwargs)
  File "/dist/ella-python/lib/python3.7/site-packages/sqlalchemy/orm/session.py", line 1046, in connection
    execution_options=execution_options)
  File "/dist/ella-python/lib/python3.7/site-packages/sqlalchemy/orm/session.py", line 1051, in _connection_for_bind
    engine, execution_options)
  File "/dist/ella-python/lib/python3.7/site-packages/sqlalchemy/orm/session.py", line 409, in _connection_for_bind
    conn = bind.contextual_connect()
  File "/dist/ella-python/lib/python3.7/site-packages/sqlalchemy/engine/base.py", line 2123, in contextual_connect
    self._wrap_pool_connect(self.pool.connect, None),
  File "/dist/ella-python/lib/python3.7/site-packages/sqlalchemy/engine/base.py", line 2162, in _wrap_pool_connect
    e, dialect, self)
  File "/dist/ella-python/lib/python3.7/site-packages/sqlalchemy/engine/base.py", line 1472, in _handle_dbapi_exception_noconnection
    util.raise_from_cause(newraise, exc_info)
  File "/dist/ella-python/lib/python3.7/site-packages/sqlalchemy/util/compat.py", line 265, in raise_from_cause
    reraise(type(exception), exception, tb=exc_tb, cause=cause)
  File "/dist/ella-python/lib/python3.7/site-packages/sqlalchemy/util/compat.py", line 248, in reraise
    raise value.with_traceback(tb)
  File "/dist/ella-python/lib/python3.7/site-packages/sqlalchemy/engine/base.py", line 2158, in _wrap_pool_connect
    return fn()
  File "/dist/ella-python/lib/python3.7/site-packages/sqlalchemy/pool.py", line 400, in connect
    return _ConnectionFairy._checkout(self)
  File "/dist/ella-python/lib/python3.7/site-packages/sqlalchemy/pool.py", line 788, in _checkout
    fairy = _ConnectionRecord.checkout(pool)
  File "/dist/ella-python/lib/python3.7/site-packages/sqlalchemy/pool.py", line 529, in checkout
    rec = pool._do_get()
  File "/dist/ella-python/lib/python3.7/site-packages/sqlalchemy/pool.py", line 1193, in _do_get
    self._dec_overflow()
  File "/dist/ella-python/lib/python3.7/site-packages/sqlalchemy/util/langhelpers.py", line 66, in __exit__
    compat.reraise(exc_type, exc_value, exc_tb)
  File "/dist/ella-python/lib/python3.7/site-packages/sqlalchemy/util/compat.py", line 249, in reraise
    raise value
  File "/dist/ella-python/lib/python3.7/site-packages/sqlalchemy/pool.py", line 1190, in _do_get
    return self._create_connection()
  File "/dist/ella-python/lib/python3.7/site-packages/sqlalchemy/pool.py", line 347, in _create_connection
    return _ConnectionRecord(self)
  File "/dist/ella-python/lib/python3.7/site-packages/sqlalchemy/pool.py", line 474, in __init__
    self.__connect(first_connect_check=True)
  File "/dist/ella-python/lib/python3.7/site-packages/sqlalchemy/pool.py", line 671, in __connect
    connection = pool._invoke_creator(self)
  File "/dist/ella-python/lib/python3.7/site-packages/sqlalchemy/engine/strategies.py", line 106, in connect
    return dialect.connect(*cargs, **cparams)
  File "/dist/ella-python/lib/python3.7/site-packages/sqlalchemy/engine/default.py", line 412, in connect
    return self.dbapi.connect(*cargs, **cparams)
  File "/dist/ella-python/lib/python3.7/site-packages/psycopg2/__init__.py", line 130, in connect
    conn = _connect(dsn, connection_factory=connection_factory, **kwasync)
psycopg2.OperationalError: could not connect to server: No such file or directory
	Is the server running locally and accepting
	connections on Unix domain socket "/socket/.s.PGSQL.5432"?

Traceback (most recent call last):
  File "src/api/polling.py", line 422, in <module>
    polling(db.session)
  File "src/api/polling.py", line 406, in polling
    raise e
  File "src/api/polling.py", line 402, in polling
    loop(session)
  File "src/api/polling.py", line 363, in loop
    session.connection()
  File "/dist/ella-python/lib/python3.7/site-packages/sqlalchemy/orm/scoping.py", line 153, in do
    return getattr(self.registry(), name)(*args, **kwargs)
  File "/dist/ella-python/lib/python3.7/site-packages/sqlalchemy/orm/session.py", line 1046, in connection
    execution_options=execution_options)
  File "/dist/ella-python/lib/python3.7/site-packages/sqlalchemy/orm/session.py", line 1051, in _connection_for_bind
    engine, execution_options)
  File "/dist/ella-python/lib/python3.7/site-packages/sqlalchemy/orm/session.py", line 409, in _connection_for_bind
    conn = bind.contextual_connect()
  File "/dist/ella-python/lib/python3.7/site-packages/sqlalchemy/engine/base.py", line 2123, in contextual_connect
    self._wrap_pool_connect(self.pool.connect, None),
  File "/dist/ella-python/lib/python3.7/site-packages/sqlalchemy/engine/base.py", line 2162, in _wrap_pool_connect
    e, dialect, self)
  File "/dist/ella-python/lib/python3.7/site-packages/sqlalchemy/engine/base.py", line 1472, in _handle_dbapi_exception_noconnection
    util.raise_from_cause(newraise, exc_info)
  File "/dist/ella-python/lib/python3.7/site-packages/sqlalchemy/util/compat.py", line 265, in raise_from_cause
    reraise(type(exception), exception, tb=exc_tb, cause=cause)
  File "/dist/ella-python/lib/python3.7/site-packages/sqlalchemy/util/compat.py", line 248, in reraise
    raise value.with_traceback(tb)
  File "/dist/ella-python/lib/python3.7/site-packages/sqlalchemy/engine/base.py", line 2158, in _wrap_pool_connect
    return fn()
  File "/dist/ella-python/lib/python3.7/site-packages/sqlalchemy/pool.py", line 400, in connect
    return _ConnectionFairy._checkout(self)
  File "/dist/ella-python/lib/python3.7/site-packages/sqlalchemy/pool.py", line 788, in _checkout
    fairy = _ConnectionRecord.checkout(pool)
  File "/dist/ella-python/lib/python3.7/site-packages/sqlalchemy/pool.py", line 529, in checkout
    rec = pool._do_get()
  File "/dist/ella-python/lib/python3.7/site-packages/sqlalchemy/pool.py", line 1193, in _do_get
    self._dec_overflow()
  File "/dist/ella-python/lib/python3.7/site-packages/sqlalchemy/util/langhelpers.py", line 66, in __exit__
    compat.reraise(exc_type, exc_value, exc_tb)
  File "/dist/ella-python/lib/python3.7/site-packages/sqlalchemy/util/compat.py", line 249, in reraise
    raise value
  File "/dist/ella-python/lib/python3.7/site-packages/sqlalchemy/pool.py", line 1190, in _do_get
    return self._create_connection()
  File "/dist/ella-python/lib/python3.7/site-packages/sqlalchemy/pool.py", line 347, in _create_connection
    return _ConnectionRecord(self)
  File "/dist/ella-python/lib/python3.7/site-packages/sqlalchemy/pool.py", line 474, in __init__
    self.__connect(first_connect_check=True)
  File "/dist/ella-python/lib/python3.7/site-packages/sqlalchemy/pool.py", line 671, in __connect
    connection = pool._invoke_creator(self)
  File "/dist/ella-python/lib/python3.7/site-packages/sqlalchemy/engine/strategies.py", line 106, in connect
    return dialect.connect(*cargs, **cparams)
  File "/dist/ella-python/lib/python3.7/site-packages/sqlalchemy/engine/default.py", line 412, in connect
    return self.dbapi.connect(*cargs, **cparams)
  File "/dist/ella-python/lib/python3.7/site-packages/psycopg2/__init__.py", line 130, in connect
    conn = _connect(dsn, connection_factory=connection_factory, **kwasync)
psycopg2.OperationalError: could not connect to server: No such file or directory
	Is the server running locally and accepting
	connections on Unix domain socket "/socket/.s.PGSQL.5432"?

2020-09-16 08:15:05,258 [INFO] __main__: Starting polling worker
2020-09-16 08:15:05,259 [INFO] __main__: Using annotation service at: http://ella-anno:6000
Traceback (most recent call last):
  File "src/api/polling.py", line 402, in polling
    loop(session)
  File "src/api/polling.py", line 363, in loop
    session.connection()
  File "/dist/ella-python/lib/python3.7/site-packages/sqlalchemy/orm/scoping.py", line 153, in do
    return getattr(self.registry(), name)(*args, **kwargs)
  File "/dist/ella-python/lib/python3.7/site-packages/sqlalchemy/orm/session.py", line 1046, in connection
    execution_options=execution_options)
  File "/dist/ella-python/lib/python3.7/site-packages/sqlalchemy/orm/session.py", line 1051, in _connection_for_bind
    engine, execution_options)
  File "/dist/ella-python/lib/python3.7/site-packages/sqlalchemy/orm/session.py", line 409, in _connection_for_bind
    conn = bind.contextual_connect()
  File "/dist/ella-python/lib/python3.7/site-packages/sqlalchemy/engine/base.py", line 2123, in contextual_connect
    self._wrap_pool_connect(self.pool.connect, None),
  File "/dist/ella-python/lib/python3.7/site-packages/sqlalchemy/engine/base.py", line 2162, in _wrap_pool_connect
    e, dialect, self)
  File "/dist/ella-python/lib/python3.7/site-packages/sqlalchemy/engine/base.py", line 1472, in _handle_dbapi_exception_noconnection
    util.raise_from_cause(newraise, exc_info)
  File "/dist/ella-python/lib/python3.7/site-packages/sqlalchemy/util/compat.py", line 265, in raise_from_cause
    reraise(type(exception), exception, tb=exc_tb, cause=cause)
  File "/dist/ella-python/lib/python3.7/site-packages/sqlalchemy/util/compat.py", line 248, in reraise
    raise value.with_traceback(tb)
  File "/dist/ella-python/lib/python3.7/site-packages/sqlalchemy/engine/base.py", line 2158, in _wrap_pool_connect
    return fn()
  File "/dist/ella-python/lib/python3.7/site-packages/sqlalchemy/pool.py", line 400, in connect
    return _ConnectionFairy._checkout(self)
  File "/dist/ella-python/lib/python3.7/site-packages/sqlalchemy/pool.py", line 788, in _checkout
    fairy = _ConnectionRecord.checkout(pool)
  File "/dist/ella-python/lib/python3.7/site-packages/sqlalchemy/pool.py", line 529, in checkout
    rec = pool._do_get()
  File "/dist/ella-python/lib/python3.7/site-packages/sqlalchemy/pool.py", line 1193, in _do_get
    self._dec_overflow()
  File "/dist/ella-python/lib/python3.7/site-packages/sqlalchemy/util/langhelpers.py", line 66, in __exit__
    compat.reraise(exc_type, exc_value, exc_tb)
  File "/dist/ella-python/lib/python3.7/site-packages/sqlalchemy/util/compat.py", line 249, in reraise
    raise value
  File "/dist/ella-python/lib/python3.7/site-packages/sqlalchemy/pool.py", line 1190, in _do_get
    return self._create_connection()
  File "/dist/ella-python/lib/python3.7/site-packages/sqlalchemy/pool.py", line 347, in _create_connection
    return _ConnectionRecord(self)
  File "/dist/ella-python/lib/python3.7/site-packages/sqlalchemy/pool.py", line 474, in __init__
    self.__connect(first_connect_check=True)
  File "/dist/ella-python/lib/python3.7/site-packages/sqlalchemy/pool.py", line 671, in __connect
    connection = pool._invoke_creator(self)
  File "/dist/ella-python/lib/python3.7/site-packages/sqlalchemy/engine/strategies.py", line 106, in connect
    return dialect.connect(*cargs, **cparams)
  File "/dist/ella-python/lib/python3.7/site-packages/sqlalchemy/engine/default.py", line 412, in connect
    return self.dbapi.connect(*cargs, **cparams)
  File "/dist/ella-python/lib/python3.7/site-packages/psycopg2/__init__.py", line 130, in connect
    conn = _connect(dsn, connection_factory=connection_factory, **kwasync)
psycopg2.OperationalError: could not connect to server: No such file or directory
	Is the server running locally and accepting
	connections on Unix domain socket "/socket/.s.PGSQL.5432"?

Traceback (most recent call last):
  File "src/api/polling.py", line 422, in <module>
    polling(db.session)
  File "src/api/polling.py", line 406, in polling
    raise e
  File "src/api/polling.py", line 402, in polling
    loop(session)
  File "src/api/polling.py", line 363, in loop
    session.connection()
  File "/dist/ella-python/lib/python3.7/site-packages/sqlalchemy/orm/scoping.py", line 153, in do
    return getattr(self.registry(), name)(*args, **kwargs)
  File "/dist/ella-python/lib/python3.7/site-packages/sqlalchemy/orm/session.py", line 1046, in connection
    execution_options=execution_options)
  File "/dist/ella-python/lib/python3.7/site-packages/sqlalchemy/orm/session.py", line 1051, in _connection_for_bind
    engine, execution_options)
  File "/dist/ella-python/lib/python3.7/site-packages/sqlalchemy/orm/session.py", line 409, in _connection_for_bind
    conn = bind.contextual_connect()
  File "/dist/ella-python/lib/python3.7/site-packages/sqlalchemy/engine/base.py", line 2123, in contextual_connect
    self._wrap_pool_connect(self.pool.connect, None),
  File "/dist/ella-python/lib/python3.7/site-packages/sqlalchemy/engine/base.py", line 2162, in _wrap_pool_connect
    e, dialect, self)
  File "/dist/ella-python/lib/python3.7/site-packages/sqlalchemy/engine/base.py", line 1472, in _handle_dbapi_exception_noconnection
    util.raise_from_cause(newraise, exc_info)
  File "/dist/ella-python/lib/python3.7/site-packages/sqlalchemy/util/compat.py", line 265, in raise_from_cause
    reraise(type(exception), exception, tb=exc_tb, cause=cause)
  File "/dist/ella-python/lib/python3.7/site-packages/sqlalchemy/util/compat.py", line 248, in reraise
    raise value.with_traceback(tb)
  File "/dist/ella-python/lib/python3.7/site-packages/sqlalchemy/engine/base.py", line 2158, in _wrap_pool_connect
    return fn()
  File "/dist/ella-python/lib/python3.7/site-packages/sqlalchemy/pool.py", line 400, in connect
    return _ConnectionFairy._checkout(self)
  File "/dist/ella-python/lib/python3.7/site-packages/sqlalchemy/pool.py", line 788, in _checkout
    fairy = _ConnectionRecord.checkout(pool)
  File "/dist/ella-python/lib/python3.7/site-packages/sqlalchemy/pool.py", line 529, in checkout
    rec = pool._do_get()
  File "/dist/ella-python/lib/python3.7/site-packages/sqlalchemy/pool.py", line 1193, in _do_get
    self._dec_overflow()
  File "/dist/ella-python/lib/python3.7/site-packages/sqlalchemy/util/langhelpers.py", line 66, in __exit__
    compat.reraise(exc_type, exc_value, exc_tb)
  File "/dist/ella-python/lib/python3.7/site-packages/sqlalchemy/util/compat.py", line 249, in reraise
    raise value
  File "/dist/ella-python/lib/python3.7/site-packages/sqlalchemy/pool.py", line 1190, in _do_get
    return self._create_connection()
  File "/dist/ella-python/lib/python3.7/site-packages/sqlalchemy/pool.py", line 347, in _create_connection
    return _ConnectionRecord(self)
  File "/dist/ella-python/lib/python3.7/site-packages/sqlalchemy/pool.py", line 474, in __init__
    self.__connect(first_connect_check=True)
  File "/dist/ella-python/lib/python3.7/site-packages/sqlalchemy/pool.py", line 671, in __connect
    connection = pool._invoke_creator(self)
  File "/dist/ella-python/lib/python3.7/site-packages/sqlalchemy/engine/strategies.py", line 106, in connect
    return dialect.connect(*cargs, **cparams)
  File "/dist/ella-python/lib/python3.7/site-packages/sqlalchemy/engine/default.py", line 412, in connect
    return self.dbapi.connect(*cargs, **cparams)
  File "/dist/ella-python/lib/python3.7/site-packages/psycopg2/__init__.py", line 130, in connect
    conn = _connect(dsn, connection_factory=connection_factory, **kwasync)
psycopg2.OperationalError: could not connect to server: No such file or directory
	Is the server running locally and accepting
	connections on Unix domain socket "/socket/.s.PGSQL.5432"?

2020-09-16 08:15:07,698 [INFO] __main__: Starting polling worker
2020-09-16 08:15:07,699 [INFO] __main__: Using annotation service at: http://ella-anno:6000
